[2021-10-24 16:59:48,283: INFO/MainProcess] Task monolith.background.send_message[9d2065c9-ed46-4ce0-9ea8-38377d245516] received
[2021-10-24 16:59:48,298: ERROR/ForkPoolWorker-4] Task monolith.background.send_message[9d2065c9-ed46-4ce0-9ea8-38377d245516] raised unexpected: RuntimeError('No application found. Either work inside a view function or push an application context. See http://flask-sqlalchemy.pocoo.org/contexts/.')
Traceback (most recent call last):
  File "/Users/antoniopace/message-in-a-bottle/venv/lib/python3.9/site-packages/sqlalchemy/util/_collections.py", line 1008, in __call__
    return self.registry[key]
KeyError: <greenlet.greenlet object at 0x7fe78bc0b7d0 (otid=0x7fe78ac4f700) current active started main>

During handling of the above exception, another exception occurred:

Traceback (most recent call last):
  File "/Users/antoniopace/message-in-a-bottle/venv/lib/python3.9/site-packages/celery/app/trace.py", line 450, in trace_task
    R = retval = fun(*args, **kwargs)
  File "/Users/antoniopace/message-in-a-bottle/venv/lib/python3.9/site-packages/celery/app/trace.py", line 731, in __protected_call__
    return self.run(*args, **kwargs)
  File "/Users/antoniopace/message-in-a-bottle/monolith/background.py", line 23, in send_message
    message.sender= data['sender']
  File "<string>", line 2, in add
  File "/Users/antoniopace/message-in-a-bottle/venv/lib/python3.9/site-packages/sqlalchemy/orm/scoping.py", line 24, in _proxied
    return self.registry()
  File "/Users/antoniopace/message-in-a-bottle/venv/lib/python3.9/site-packages/sqlalchemy/util/_collections.py", line 1010, in __call__
    return self.registry.setdefault(key, self.createfunc())
  File "/Users/antoniopace/message-in-a-bottle/venv/lib/python3.9/site-packages/sqlalchemy/orm/session.py", line 4172, in __call__
    return self.class_(**local_kw)
  File "/Users/antoniopace/message-in-a-bottle/venv/lib/python3.9/site-packages/flask_sqlalchemy/__init__.py", line 174, in __init__
    self.app = app = db.get_app()
  File "/Users/antoniopace/message-in-a-bottle/venv/lib/python3.9/site-packages/flask_sqlalchemy/__init__.py", line 1042, in get_app
    raise RuntimeError(
RuntimeError: No application found. Either work inside a view function or push an application context. See http://flask-sqlalchemy.pocoo.org/contexts/.
[2021-10-24 16:59:49,026: INFO/MainProcess] Task monolith.background.send_message[af46c399-d36f-4b6b-919e-36f0437e8d64] received
[2021-10-24 16:59:49,042: ERROR/ForkPoolWorker-4] Task monolith.background.send_message[af46c399-d36f-4b6b-919e-36f0437e8d64] raised unexpected: RuntimeError('No application found. Either work inside a view function or push an application context. See http://flask-sqlalchemy.pocoo.org/contexts/.')
Traceback (most recent call last):
  File "/Users/antoniopace/message-in-a-bottle/venv/lib/python3.9/site-packages/sqlalchemy/util/_collections.py", line 1008, in __call__
    return self.registry[key]
KeyError: <greenlet.greenlet object at 0x7fe78bc0b7d0 (otid=0x7fe78ac4f700) current active started main>

During handling of the above exception, another exception occurred:

Traceback (most recent call last):
  File "/Users/antoniopace/message-in-a-bottle/venv/lib/python3.9/site-packages/celery/app/trace.py", line 450, in trace_task
    R = retval = fun(*args, **kwargs)
  File "/Users/antoniopace/message-in-a-bottle/venv/lib/python3.9/site-packages/celery/app/trace.py", line 731, in __protected_call__
    return self.run(*args, **kwargs)
  File "/Users/antoniopace/message-in-a-bottle/monolith/background.py", line 23, in send_message
    message.sender= data['sender']
  File "<string>", line 2, in add
  File "/Users/antoniopace/message-in-a-bottle/venv/lib/python3.9/site-packages/sqlalchemy/orm/scoping.py", line 24, in _proxied
    return self.registry()
  File "/Users/antoniopace/message-in-a-bottle/venv/lib/python3.9/site-packages/sqlalchemy/util/_collections.py", line 1010, in __call__
    return self.registry.setdefault(key, self.createfunc())
  File "/Users/antoniopace/message-in-a-bottle/venv/lib/python3.9/site-packages/sqlalchemy/orm/session.py", line 4172, in __call__
    return self.class_(**local_kw)
  File "/Users/antoniopace/message-in-a-bottle/venv/lib/python3.9/site-packages/flask_sqlalchemy/__init__.py", line 174, in __init__
    self.app = app = db.get_app()
  File "/Users/antoniopace/message-in-a-bottle/venv/lib/python3.9/site-packages/flask_sqlalchemy/__init__.py", line 1042, in get_app
    raise RuntimeError(
RuntimeError: No application found. Either work inside a view function or push an application context. See http://flask-sqlalchemy.pocoo.org/contexts/.
[2021-10-24 16:59:50,884: INFO/MainProcess] Task monolith.background.send_message[d92dd388-31f0-44a3-9432-5485feadbb8e] received
[2021-10-24 16:59:50,897: ERROR/ForkPoolWorker-4] Task monolith.background.send_message[d92dd388-31f0-44a3-9432-5485feadbb8e] raised unexpected: RuntimeError('No application found. Either work inside a view function or push an application context. See http://flask-sqlalchemy.pocoo.org/contexts/.')
Traceback (most recent call last):
  File "/Users/antoniopace/message-in-a-bottle/venv/lib/python3.9/site-packages/sqlalchemy/util/_collections.py", line 1008, in __call__
    return self.registry[key]
KeyError: <greenlet.greenlet object at 0x7fe78bc0b7d0 (otid=0x7fe78ac4f700) current active started main>

During handling of the above exception, another exception occurred:

Traceback (most recent call last):
  File "/Users/antoniopace/message-in-a-bottle/venv/lib/python3.9/site-packages/celery/app/trace.py", line 450, in trace_task
    R = retval = fun(*args, **kwargs)
  File "/Users/antoniopace/message-in-a-bottle/venv/lib/python3.9/site-packages/celery/app/trace.py", line 731, in __protected_call__
    return self.run(*args, **kwargs)
  File "/Users/antoniopace/message-in-a-bottle/monolith/background.py", line 23, in send_message
    message.sender= data['sender']
  File "<string>", line 2, in add
  File "/Users/antoniopace/message-in-a-bottle/venv/lib/python3.9/site-packages/sqlalchemy/orm/scoping.py", line 24, in _proxied
    return self.registry()
  File "/Users/antoniopace/message-in-a-bottle/venv/lib/python3.9/site-packages/sqlalchemy/util/_collections.py", line 1010, in __call__
    return self.registry.setdefault(key, self.createfunc())
  File "/Users/antoniopace/message-in-a-bottle/venv/lib/python3.9/site-packages/sqlalchemy/orm/session.py", line 4172, in __call__
    return self.class_(**local_kw)
  File "/Users/antoniopace/message-in-a-bottle/venv/lib/python3.9/site-packages/flask_sqlalchemy/__init__.py", line 174, in __init__
    self.app = app = db.get_app()
  File "/Users/antoniopace/message-in-a-bottle/venv/lib/python3.9/site-packages/flask_sqlalchemy/__init__.py", line 1042, in get_app
    raise RuntimeError(
RuntimeError: No application found. Either work inside a view function or push an application context. See http://flask-sqlalchemy.pocoo.org/contexts/.
[2021-10-24 17:01:13,272: INFO/MainProcess] Task monolith.background.send_message[633fcbb3-d16b-4845-86de-6134cb6e9ab0] received
[2021-10-24 17:01:13,302: WARNING/ForkPoolWorker-2] <Message 59>
[2021-10-24 17:01:13,303: WARNING/ForkPoolWorker-2] 

[2021-10-24 17:01:13,317: INFO/ForkPoolWorker-2] Task monolith.background.send_message[633fcbb3-d16b-4845-86de-6134cb6e9ab0] succeeded in 0.040475620999998796s: []
[2021-10-24 17:01:21,603: INFO/MainProcess] Task monolith.background.send_message[6ba5e98b-f4c4-4ad8-9265-e3a7b5380371] received
[2021-10-24 17:01:21,617: ERROR/ForkPoolWorker-4] Task monolith.background.send_message[6ba5e98b-f4c4-4ad8-9265-e3a7b5380371] raised unexpected: RuntimeError('No application found. Either work inside a view function or push an application context. See http://flask-sqlalchemy.pocoo.org/contexts/.')
Traceback (most recent call last):
  File "/Users/antoniopace/message-in-a-bottle/venv/lib/python3.9/site-packages/sqlalchemy/util/_collections.py", line 1008, in __call__
    return self.registry[key]
KeyError: <greenlet.greenlet object at 0x7fe78bc0b7d0 (otid=0x7fe78ac4f700) current active started main>

During handling of the above exception, another exception occurred:

Traceback (most recent call last):
  File "/Users/antoniopace/message-in-a-bottle/venv/lib/python3.9/site-packages/celery/app/trace.py", line 450, in trace_task
    R = retval = fun(*args, **kwargs)
  File "/Users/antoniopace/message-in-a-bottle/venv/lib/python3.9/site-packages/celery/app/trace.py", line 731, in __protected_call__
    return self.run(*args, **kwargs)
  File "/Users/antoniopace/message-in-a-bottle/monolith/background.py", line 23, in send_message
    message.sender= data['sender']
  File "<string>", line 2, in add
  File "/Users/antoniopace/message-in-a-bottle/venv/lib/python3.9/site-packages/sqlalchemy/orm/scoping.py", line 24, in _proxied
    return self.registry()
  File "/Users/antoniopace/message-in-a-bottle/venv/lib/python3.9/site-packages/sqlalchemy/util/_collections.py", line 1010, in __call__
    return self.registry.setdefault(key, self.createfunc())
  File "/Users/antoniopace/message-in-a-bottle/venv/lib/python3.9/site-packages/sqlalchemy/orm/session.py", line 4172, in __call__
    return self.class_(**local_kw)
  File "/Users/antoniopace/message-in-a-bottle/venv/lib/python3.9/site-packages/flask_sqlalchemy/__init__.py", line 174, in __init__
    self.app = app = db.get_app()
  File "/Users/antoniopace/message-in-a-bottle/venv/lib/python3.9/site-packages/flask_sqlalchemy/__init__.py", line 1042, in get_app
    raise RuntimeError(
RuntimeError: No application found. Either work inside a view function or push an application context. See http://flask-sqlalchemy.pocoo.org/contexts/.
[2021-10-24 17:01:22,588: INFO/MainProcess] Task monolith.background.send_message[4886bac0-5996-4dd8-b0c9-d143ef0b2253] received
[2021-10-24 17:01:22,601: ERROR/ForkPoolWorker-4] Task monolith.background.send_message[4886bac0-5996-4dd8-b0c9-d143ef0b2253] raised unexpected: RuntimeError('No application found. Either work inside a view function or push an application context. See http://flask-sqlalchemy.pocoo.org/contexts/.')
Traceback (most recent call last):
  File "/Users/antoniopace/message-in-a-bottle/venv/lib/python3.9/site-packages/sqlalchemy/util/_collections.py", line 1008, in __call__
    return self.registry[key]
KeyError: <greenlet.greenlet object at 0x7fe78bc0b7d0 (otid=0x7fe78ac4f700) current active started main>

During handling of the above exception, another exception occurred:

Traceback (most recent call last):
  File "/Users/antoniopace/message-in-a-bottle/venv/lib/python3.9/site-packages/celery/app/trace.py", line 450, in trace_task
    R = retval = fun(*args, **kwargs)
  File "/Users/antoniopace/message-in-a-bottle/venv/lib/python3.9/site-packages/celery/app/trace.py", line 731, in __protected_call__
    return self.run(*args, **kwargs)
  File "/Users/antoniopace/message-in-a-bottle/monolith/background.py", line 23, in send_message
    message.sender= data['sender']
  File "<string>", line 2, in add
  File "/Users/antoniopace/message-in-a-bottle/venv/lib/python3.9/site-packages/sqlalchemy/orm/scoping.py", line 24, in _proxied
    return self.registry()
  File "/Users/antoniopace/message-in-a-bottle/venv/lib/python3.9/site-packages/sqlalchemy/util/_collections.py", line 1010, in __call__
    return self.registry.setdefault(key, self.createfunc())
  File "/Users/antoniopace/message-in-a-bottle/venv/lib/python3.9/site-packages/sqlalchemy/orm/session.py", line 4172, in __call__
    return self.class_(**local_kw)
  File "/Users/antoniopace/message-in-a-bottle/venv/lib/python3.9/site-packages/flask_sqlalchemy/__init__.py", line 174, in __init__
    self.app = app = db.get_app()
  File "/Users/antoniopace/message-in-a-bottle/venv/lib/python3.9/site-packages/flask_sqlalchemy/__init__.py", line 1042, in get_app
    raise RuntimeError(
RuntimeError: No application found. Either work inside a view function or push an application context. See http://flask-sqlalchemy.pocoo.org/contexts/.
[2021-10-24 17:01:23,436: INFO/MainProcess] Task monolith.background.send_message[2a44f71e-529e-4c06-a519-06d1c48c4689] received
[2021-10-24 17:01:23,454: WARNING/ForkPoolWorker-2] <Message 60>
[2021-10-24 17:01:23,455: WARNING/ForkPoolWorker-2] 

[2021-10-24 17:01:23,459: INFO/ForkPoolWorker-2] Task monolith.background.send_message[2a44f71e-529e-4c06-a519-06d1c48c4689] succeeded in 0.021775770999994393s: []
[2021-10-24 17:01:24,273: INFO/MainProcess] Task monolith.background.send_message[fda34b44-86b8-4855-8c3c-1befe9425c13] received
[2021-10-24 17:01:24,286: WARNING/ForkPoolWorker-2] <Message 61>
[2021-10-24 17:01:24,287: WARNING/ForkPoolWorker-2] 

[2021-10-24 17:01:24,289: INFO/ForkPoolWorker-2] Task monolith.background.send_message[fda34b44-86b8-4855-8c3c-1befe9425c13] succeeded in 0.01468317599999125s: []
[2021-10-24 17:01:25,732: INFO/MainProcess] Task monolith.background.send_message[c4f56089-a408-422c-b66a-4092f09dbd5a] received
[2021-10-24 17:01:25,749: WARNING/ForkPoolWorker-2] <Message 62>
[2021-10-24 17:01:25,750: WARNING/ForkPoolWorker-2] 

[2021-10-24 17:01:25,755: INFO/ForkPoolWorker-2] Task monolith.background.send_message[c4f56089-a408-422c-b66a-4092f09dbd5a] succeeded in 0.02199768500000232s: []
[2021-10-24 17:01:26,957: INFO/MainProcess] Task monolith.background.send_message[409544c1-984c-467a-9c1d-0959624cb8dd] received
[2021-10-24 17:01:26,970: ERROR/ForkPoolWorker-4] Task monolith.background.send_message[409544c1-984c-467a-9c1d-0959624cb8dd] raised unexpected: RuntimeError('No application found. Either work inside a view function or push an application context. See http://flask-sqlalchemy.pocoo.org/contexts/.')
Traceback (most recent call last):
  File "/Users/antoniopace/message-in-a-bottle/venv/lib/python3.9/site-packages/sqlalchemy/util/_collections.py", line 1008, in __call__
    return self.registry[key]
KeyError: <greenlet.greenlet object at 0x7fe78bc0b7d0 (otid=0x7fe78ac4f700) current active started main>

During handling of the above exception, another exception occurred:

Traceback (most recent call last):
  File "/Users/antoniopace/message-in-a-bottle/venv/lib/python3.9/site-packages/celery/app/trace.py", line 450, in trace_task
    R = retval = fun(*args, **kwargs)
  File "/Users/antoniopace/message-in-a-bottle/venv/lib/python3.9/site-packages/celery/app/trace.py", line 731, in __protected_call__
    return self.run(*args, **kwargs)
  File "/Users/antoniopace/message-in-a-bottle/monolith/background.py", line 23, in send_message
    message.sender= data['sender']
  File "<string>", line 2, in add
  File "/Users/antoniopace/message-in-a-bottle/venv/lib/python3.9/site-packages/sqlalchemy/orm/scoping.py", line 24, in _proxied
    return self.registry()
  File "/Users/antoniopace/message-in-a-bottle/venv/lib/python3.9/site-packages/sqlalchemy/util/_collections.py", line 1010, in __call__
    return self.registry.setdefault(key, self.createfunc())
  File "/Users/antoniopace/message-in-a-bottle/venv/lib/python3.9/site-packages/sqlalchemy/orm/session.py", line 4172, in __call__
    return self.class_(**local_kw)
  File "/Users/antoniopace/message-in-a-bottle/venv/lib/python3.9/site-packages/flask_sqlalchemy/__init__.py", line 174, in __init__
    self.app = app = db.get_app()
  File "/Users/antoniopace/message-in-a-bottle/venv/lib/python3.9/site-packages/flask_sqlalchemy/__init__.py", line 1042, in get_app
    raise RuntimeError(
RuntimeError: No application found. Either work inside a view function or push an application context. See http://flask-sqlalchemy.pocoo.org/contexts/.
[2021-10-24 17:01:27,700: INFO/MainProcess] Task monolith.background.send_message[b0af6332-fabe-44aa-9794-193ca479ad07] received
[2021-10-24 17:01:27,718: WARNING/ForkPoolWorker-2] <Message 63>
[2021-10-24 17:01:27,718: WARNING/ForkPoolWorker-2] 

[2021-10-24 17:01:27,723: INFO/ForkPoolWorker-2] Task monolith.background.send_message[b0af6332-fabe-44aa-9794-193ca479ad07] succeeded in 0.02132842700000026s: []
[2021-10-24 17:01:28,409: INFO/MainProcess] Task monolith.background.send_message[3c3cc216-f196-42e7-8242-c49bba97d368] received
[2021-10-24 17:01:28,426: WARNING/ForkPoolWorker-2] <Message 64>
[2021-10-24 17:01:28,426: WARNING/ForkPoolWorker-2] 

[2021-10-24 17:01:28,438: INFO/ForkPoolWorker-2] Task monolith.background.send_message[3c3cc216-f196-42e7-8242-c49bba97d368] succeeded in 0.02658985299999017s: []
[2021-10-24 17:01:29,037: INFO/MainProcess] Task monolith.background.send_message[282f40f4-439e-4b2b-ab19-34c91a44958b] received
[2021-10-24 17:01:29,053: ERROR/ForkPoolWorker-4] Task monolith.background.send_message[282f40f4-439e-4b2b-ab19-34c91a44958b] raised unexpected: RuntimeError('No application found. Either work inside a view function or push an application context. See http://flask-sqlalchemy.pocoo.org/contexts/.')
Traceback (most recent call last):
  File "/Users/antoniopace/message-in-a-bottle/venv/lib/python3.9/site-packages/sqlalchemy/util/_collections.py", line 1008, in __call__
    return self.registry[key]
KeyError: <greenlet.greenlet object at 0x7fe78bc0b7d0 (otid=0x7fe78ac4f700) current active started main>

During handling of the above exception, another exception occurred:

Traceback (most recent call last):
  File "/Users/antoniopace/message-in-a-bottle/venv/lib/python3.9/site-packages/celery/app/trace.py", line 450, in trace_task
    R = retval = fun(*args, **kwargs)
  File "/Users/antoniopace/message-in-a-bottle/venv/lib/python3.9/site-packages/celery/app/trace.py", line 731, in __protected_call__
    return self.run(*args, **kwargs)
  File "/Users/antoniopace/message-in-a-bottle/monolith/background.py", line 23, in send_message
    message.sender= data['sender']
  File "<string>", line 2, in add
  File "/Users/antoniopace/message-in-a-bottle/venv/lib/python3.9/site-packages/sqlalchemy/orm/scoping.py", line 24, in _proxied
    return self.registry()
  File "/Users/antoniopace/message-in-a-bottle/venv/lib/python3.9/site-packages/sqlalchemy/util/_collections.py", line 1010, in __call__
    return self.registry.setdefault(key, self.createfunc())
  File "/Users/antoniopace/message-in-a-bottle/venv/lib/python3.9/site-packages/sqlalchemy/orm/session.py", line 4172, in __call__
    return self.class_(**local_kw)
  File "/Users/antoniopace/message-in-a-bottle/venv/lib/python3.9/site-packages/flask_sqlalchemy/__init__.py", line 174, in __init__
    self.app = app = db.get_app()
  File "/Users/antoniopace/message-in-a-bottle/venv/lib/python3.9/site-packages/flask_sqlalchemy/__init__.py", line 1042, in get_app
    raise RuntimeError(
RuntimeError: No application found. Either work inside a view function or push an application context. See http://flask-sqlalchemy.pocoo.org/contexts/.
[2021-10-24 17:01:29,674: INFO/MainProcess] Task monolith.background.send_message[35fd4396-9650-4e64-a7ed-9a069ccf8913] received
[2021-10-24 17:01:29,686: ERROR/ForkPoolWorker-4] Task monolith.background.send_message[35fd4396-9650-4e64-a7ed-9a069ccf8913] raised unexpected: RuntimeError('No application found. Either work inside a view function or push an application context. See http://flask-sqlalchemy.pocoo.org/contexts/.')
Traceback (most recent call last):
  File "/Users/antoniopace/message-in-a-bottle/venv/lib/python3.9/site-packages/sqlalchemy/util/_collections.py", line 1008, in __call__
    return self.registry[key]
KeyError: <greenlet.greenlet object at 0x7fe78bc0b7d0 (otid=0x7fe78ac4f700) current active started main>

During handling of the above exception, another exception occurred:

Traceback (most recent call last):
  File "/Users/antoniopace/message-in-a-bottle/venv/lib/python3.9/site-packages/celery/app/trace.py", line 450, in trace_task
    R = retval = fun(*args, **kwargs)
  File "/Users/antoniopace/message-in-a-bottle/venv/lib/python3.9/site-packages/celery/app/trace.py", line 731, in __protected_call__
    return self.run(*args, **kwargs)
  File "/Users/antoniopace/message-in-a-bottle/monolith/background.py", line 23, in send_message
    message.sender= data['sender']
  File "<string>", line 2, in add
  File "/Users/antoniopace/message-in-a-bottle/venv/lib/python3.9/site-packages/sqlalchemy/orm/scoping.py", line 24, in _proxied
    return self.registry()
  File "/Users/antoniopace/message-in-a-bottle/venv/lib/python3.9/site-packages/sqlalchemy/util/_collections.py", line 1010, in __call__
    return self.registry.setdefault(key, self.createfunc())
  File "/Users/antoniopace/message-in-a-bottle/venv/lib/python3.9/site-packages/sqlalchemy/orm/session.py", line 4172, in __call__
    return self.class_(**local_kw)
  File "/Users/antoniopace/message-in-a-bottle/venv/lib/python3.9/site-packages/flask_sqlalchemy/__init__.py", line 174, in __init__
    self.app = app = db.get_app()
  File "/Users/antoniopace/message-in-a-bottle/venv/lib/python3.9/site-packages/flask_sqlalchemy/__init__.py", line 1042, in get_app
    raise RuntimeError(
RuntimeError: No application found. Either work inside a view function or push an application context. See http://flask-sqlalchemy.pocoo.org/contexts/.
[2021-10-24 17:01:30,435: INFO/MainProcess] Task monolith.background.send_message[8c1e2e79-8cff-42e4-83be-36a741dada9c] received
[2021-10-24 17:01:30,455: WARNING/ForkPoolWorker-2] <Message 65>
[2021-10-24 17:01:30,455: WARNING/ForkPoolWorker-2] 

[2021-10-24 17:01:30,460: INFO/ForkPoolWorker-2] Task monolith.background.send_message[8c1e2e79-8cff-42e4-83be-36a741dada9c] succeeded in 0.02410886100000198s: []
[2021-10-24 17:01:31,213: INFO/MainProcess] Task monolith.background.send_message[b612da7d-0ae4-4ebe-a140-64ed4300eced] received
[2021-10-24 17:01:31,230: WARNING/ForkPoolWorker-2] <Message 66>
[2021-10-24 17:01:31,230: WARNING/ForkPoolWorker-2] 

[2021-10-24 17:01:31,234: INFO/ForkPoolWorker-2] Task monolith.background.send_message[b612da7d-0ae4-4ebe-a140-64ed4300eced] succeeded in 0.019740145000000098s: []
[2021-10-24 17:01:31,786: INFO/MainProcess] Task monolith.background.send_message[42ae4d69-a859-472e-9a54-d73f4255f504] received
[2021-10-24 17:01:31,809: WARNING/ForkPoolWorker-2] <Message 67>
[2021-10-24 17:01:31,810: WARNING/ForkPoolWorker-2] 

[2021-10-24 17:01:31,815: INFO/ForkPoolWorker-2] Task monolith.background.send_message[42ae4d69-a859-472e-9a54-d73f4255f504] succeeded in 0.02751632700000073s: []
[2021-10-24 17:01:32,349: INFO/MainProcess] Task monolith.background.send_message[c0603646-7b66-4f0f-ad14-93947d442eda] received
[2021-10-24 17:01:32,363: ERROR/ForkPoolWorker-4] Task monolith.background.send_message[c0603646-7b66-4f0f-ad14-93947d442eda] raised unexpected: RuntimeError('No application found. Either work inside a view function or push an application context. See http://flask-sqlalchemy.pocoo.org/contexts/.')
Traceback (most recent call last):
  File "/Users/antoniopace/message-in-a-bottle/venv/lib/python3.9/site-packages/sqlalchemy/util/_collections.py", line 1008, in __call__
    return self.registry[key]
KeyError: <greenlet.greenlet object at 0x7fe78bc0b7d0 (otid=0x7fe78ac4f700) current active started main>

During handling of the above exception, another exception occurred:

Traceback (most recent call last):
  File "/Users/antoniopace/message-in-a-bottle/venv/lib/python3.9/site-packages/celery/app/trace.py", line 450, in trace_task
    R = retval = fun(*args, **kwargs)
  File "/Users/antoniopace/message-in-a-bottle/venv/lib/python3.9/site-packages/celery/app/trace.py", line 731, in __protected_call__
    return self.run(*args, **kwargs)
  File "/Users/antoniopace/message-in-a-bottle/monolith/background.py", line 23, in send_message
    message.sender= data['sender']
  File "<string>", line 2, in add
  File "/Users/antoniopace/message-in-a-bottle/venv/lib/python3.9/site-packages/sqlalchemy/orm/scoping.py", line 24, in _proxied
    return self.registry()
  File "/Users/antoniopace/message-in-a-bottle/venv/lib/python3.9/site-packages/sqlalchemy/util/_collections.py", line 1010, in __call__
    return self.registry.setdefault(key, self.createfunc())
  File "/Users/antoniopace/message-in-a-bottle/venv/lib/python3.9/site-packages/sqlalchemy/orm/session.py", line 4172, in __call__
    return self.class_(**local_kw)
  File "/Users/antoniopace/message-in-a-bottle/venv/lib/python3.9/site-packages/flask_sqlalchemy/__init__.py", line 174, in __init__
    self.app = app = db.get_app()
  File "/Users/antoniopace/message-in-a-bottle/venv/lib/python3.9/site-packages/flask_sqlalchemy/__init__.py", line 1042, in get_app
    raise RuntimeError(
RuntimeError: No application found. Either work inside a view function or push an application context. See http://flask-sqlalchemy.pocoo.org/contexts/.
[2021-10-24 17:01:32,965: INFO/MainProcess] Task monolith.background.send_message[b6d81ac3-ac94-407f-a347-fdb837ac8e30] received
[2021-10-24 17:01:32,977: ERROR/ForkPoolWorker-4] Task monolith.background.send_message[b6d81ac3-ac94-407f-a347-fdb837ac8e30] raised unexpected: RuntimeError('No application found. Either work inside a view function or push an application context. See http://flask-sqlalchemy.pocoo.org/contexts/.')
Traceback (most recent call last):
  File "/Users/antoniopace/message-in-a-bottle/venv/lib/python3.9/site-packages/sqlalchemy/util/_collections.py", line 1008, in __call__
    return self.registry[key]
KeyError: <greenlet.greenlet object at 0x7fe78bc0b7d0 (otid=0x7fe78ac4f700) current active started main>

During handling of the above exception, another exception occurred:

Traceback (most recent call last):
  File "/Users/antoniopace/message-in-a-bottle/venv/lib/python3.9/site-packages/celery/app/trace.py", line 450, in trace_task
    R = retval = fun(*args, **kwargs)
  File "/Users/antoniopace/message-in-a-bottle/venv/lib/python3.9/site-packages/celery/app/trace.py", line 731, in __protected_call__
    return self.run(*args, **kwargs)
  File "/Users/antoniopace/message-in-a-bottle/monolith/background.py", line 23, in send_message
    message.sender= data['sender']
  File "<string>", line 2, in add
  File "/Users/antoniopace/message-in-a-bottle/venv/lib/python3.9/site-packages/sqlalchemy/orm/scoping.py", line 24, in _proxied
    return self.registry()
  File "/Users/antoniopace/message-in-a-bottle/venv/lib/python3.9/site-packages/sqlalchemy/util/_collections.py", line 1010, in __call__
    return self.registry.setdefault(key, self.createfunc())
  File "/Users/antoniopace/message-in-a-bottle/venv/lib/python3.9/site-packages/sqlalchemy/orm/session.py", line 4172, in __call__
    return self.class_(**local_kw)
  File "/Users/antoniopace/message-in-a-bottle/venv/lib/python3.9/site-packages/flask_sqlalchemy/__init__.py", line 174, in __init__
    self.app = app = db.get_app()
  File "/Users/antoniopace/message-in-a-bottle/venv/lib/python3.9/site-packages/flask_sqlalchemy/__init__.py", line 1042, in get_app
    raise RuntimeError(
RuntimeError: No application found. Either work inside a view function or push an application context. See http://flask-sqlalchemy.pocoo.org/contexts/.
[2021-10-24 17:01:33,539: INFO/MainProcess] Task monolith.background.send_message[f116b518-6d81-4178-9ce9-dfa6dd0c6166] received
[2021-10-24 17:01:33,555: WARNING/ForkPoolWorker-2] <Message 68>
[2021-10-24 17:01:33,556: WARNING/ForkPoolWorker-2] 

[2021-10-24 17:01:33,560: INFO/ForkPoolWorker-2] Task monolith.background.send_message[f116b518-6d81-4178-9ce9-dfa6dd0c6166] succeeded in 0.019775620999993748s: []
[2021-10-24 17:02:40,758: INFO/MainProcess] Task monolith.background.send_message[5a092873-286a-4460-9a72-3df9a25ff417] received
[2021-10-24 17:02:40,772: ERROR/ForkPoolWorker-4] Task monolith.background.send_message[5a092873-286a-4460-9a72-3df9a25ff417] raised unexpected: RuntimeError('No application found. Either work inside a view function or push an application context. See http://flask-sqlalchemy.pocoo.org/contexts/.')
Traceback (most recent call last):
  File "/Users/antoniopace/message-in-a-bottle/venv/lib/python3.9/site-packages/sqlalchemy/util/_collections.py", line 1008, in __call__
    return self.registry[key]
KeyError: <greenlet.greenlet object at 0x7fe78bc0b7d0 (otid=0x7fe78ac4f700) current active started main>

During handling of the above exception, another exception occurred:

Traceback (most recent call last):
  File "/Users/antoniopace/message-in-a-bottle/venv/lib/python3.9/site-packages/celery/app/trace.py", line 450, in trace_task
    R = retval = fun(*args, **kwargs)
  File "/Users/antoniopace/message-in-a-bottle/venv/lib/python3.9/site-packages/celery/app/trace.py", line 731, in __protected_call__
    return self.run(*args, **kwargs)
  File "/Users/antoniopace/message-in-a-bottle/monolith/background.py", line 23, in send_message
    print(message)
  File "<string>", line 2, in add
  File "/Users/antoniopace/message-in-a-bottle/venv/lib/python3.9/site-packages/sqlalchemy/orm/scoping.py", line 24, in _proxied
    return self.registry()
  File "/Users/antoniopace/message-in-a-bottle/venv/lib/python3.9/site-packages/sqlalchemy/util/_collections.py", line 1010, in __call__
    return self.registry.setdefault(key, self.createfunc())
  File "/Users/antoniopace/message-in-a-bottle/venv/lib/python3.9/site-packages/sqlalchemy/orm/session.py", line 4172, in __call__
    return self.class_(**local_kw)
  File "/Users/antoniopace/message-in-a-bottle/venv/lib/python3.9/site-packages/flask_sqlalchemy/__init__.py", line 174, in __init__
    self.app = app = db.get_app()
  File "/Users/antoniopace/message-in-a-bottle/venv/lib/python3.9/site-packages/flask_sqlalchemy/__init__.py", line 1042, in get_app
    raise RuntimeError(
RuntimeError: No application found. Either work inside a view function or push an application context. See http://flask-sqlalchemy.pocoo.org/contexts/.
[2021-10-24 17:02:41,704: INFO/MainProcess] Task monolith.background.send_message[7e0c6609-6cf6-4fa9-9d2b-f2156f5a9760] received
[2021-10-24 17:02:41,725: ERROR/ForkPoolWorker-4] Task monolith.background.send_message[7e0c6609-6cf6-4fa9-9d2b-f2156f5a9760] raised unexpected: RuntimeError('No application found. Either work inside a view function or push an application context. See http://flask-sqlalchemy.pocoo.org/contexts/.')
Traceback (most recent call last):
  File "/Users/antoniopace/message-in-a-bottle/venv/lib/python3.9/site-packages/sqlalchemy/util/_collections.py", line 1008, in __call__
    return self.registry[key]
KeyError: <greenlet.greenlet object at 0x7fe78bc0b7d0 (otid=0x7fe78ac4f700) current active started main>

During handling of the above exception, another exception occurred:

Traceback (most recent call last):
  File "/Users/antoniopace/message-in-a-bottle/venv/lib/python3.9/site-packages/celery/app/trace.py", line 450, in trace_task
    R = retval = fun(*args, **kwargs)
  File "/Users/antoniopace/message-in-a-bottle/venv/lib/python3.9/site-packages/celery/app/trace.py", line 731, in __protected_call__
    return self.run(*args, **kwargs)
  File "/Users/antoniopace/message-in-a-bottle/monolith/background.py", line 23, in send_message
    print(message)
  File "<string>", line 2, in add
  File "/Users/antoniopace/message-in-a-bottle/venv/lib/python3.9/site-packages/sqlalchemy/orm/scoping.py", line 24, in _proxied
    return self.registry()
  File "/Users/antoniopace/message-in-a-bottle/venv/lib/python3.9/site-packages/sqlalchemy/util/_collections.py", line 1010, in __call__
    return self.registry.setdefault(key, self.createfunc())
  File "/Users/antoniopace/message-in-a-bottle/venv/lib/python3.9/site-packages/sqlalchemy/orm/session.py", line 4172, in __call__
    return self.class_(**local_kw)
  File "/Users/antoniopace/message-in-a-bottle/venv/lib/python3.9/site-packages/flask_sqlalchemy/__init__.py", line 174, in __init__
    self.app = app = db.get_app()
  File "/Users/antoniopace/message-in-a-bottle/venv/lib/python3.9/site-packages/flask_sqlalchemy/__init__.py", line 1042, in get_app
    raise RuntimeError(
RuntimeError: No application found. Either work inside a view function or push an application context. See http://flask-sqlalchemy.pocoo.org/contexts/.
[2021-10-24 17:02:42,382: INFO/MainProcess] Task monolith.background.send_message[44311199-bf81-402d-9f64-a45070b985d3] received
[2021-10-24 17:02:42,418: WARNING/ForkPoolWorker-2] <Message 69>
[2021-10-24 17:02:42,419: WARNING/ForkPoolWorker-2] 

[2021-10-24 17:02:42,424: INFO/ForkPoolWorker-2] Task monolith.background.send_message[44311199-bf81-402d-9f64-a45070b985d3] succeeded in 0.03651745900000947s: []

SIGHUP not supported: Restarting with SIGHUP is unstable on this platform!
[2021-10-24 17:05:39,881: ERROR/MainProcess] Process 'ForkPoolWorker-4' pid:73256 exited with 'exitcode 70'
[2021-10-24 17:05:39,896: ERROR/MainProcess] Process 'ForkPoolWorker-3' pid:73255 exited with 'exitcode 70'
[2021-10-24 17:05:39,909: ERROR/MainProcess] Process 'ForkPoolWorker-2' pid:73254 exited with 'exitcode 70'
[2021-10-24 17:05:39,922: ERROR/MainProcess] Process 'ForkPoolWorker-1' pid:73253 exited with 'exitcode 70'
[2021-10-24 17:08:55,160: INFO/MainProcess] Task monolith.background.send_message[95089200-cdb4-46ef-a73e-a34327a9c5c3] received
[2021-10-24 17:08:55,215: ERROR/ForkPoolWorker-4] Task monolith.background.send_message[95089200-cdb4-46ef-a73e-a34327a9c5c3] raised unexpected: RuntimeError('No application found. Either work inside a view function or push an application context. See http://flask-sqlalchemy.pocoo.org/contexts/.')
Traceback (most recent call last):
  File "/Users/antoniopace/message-in-a-bottle/venv/lib/python3.9/site-packages/sqlalchemy/util/_collections.py", line 1008, in __call__
    return self.registry[key]
KeyError: <greenlet.greenlet object at 0x7fe78bc0b7d0 (otid=0x7fe78ac4f700) current active started main>

During handling of the above exception, another exception occurred:

Traceback (most recent call last):
  File "/Users/antoniopace/message-in-a-bottle/venv/lib/python3.9/site-packages/celery/app/trace.py", line 450, in trace_task
    R = retval = fun(*args, **kwargs)
  File "/Users/antoniopace/message-in-a-bottle/venv/lib/python3.9/site-packages/celery/app/trace.py", line 731, in __protected_call__
    return self.run(*args, **kwargs)
  File "/Users/antoniopace/message-in-a-bottle/monolith/background.py", line 23, in send_message
    message.receiver= data['receiver']
  File "<string>", line 2, in add
  File "/Users/antoniopace/message-in-a-bottle/venv/lib/python3.9/site-packages/sqlalchemy/orm/scoping.py", line 24, in _proxied
    return self.registry()
  File "/Users/antoniopace/message-in-a-bottle/venv/lib/python3.9/site-packages/sqlalchemy/util/_collections.py", line 1010, in __call__
    return self.registry.setdefault(key, self.createfunc())
  File "/Users/antoniopace/message-in-a-bottle/venv/lib/python3.9/site-packages/sqlalchemy/orm/session.py", line 4172, in __call__
    return self.class_(**local_kw)
  File "/Users/antoniopace/message-in-a-bottle/venv/lib/python3.9/site-packages/flask_sqlalchemy/__init__.py", line 174, in __init__
    self.app = app = db.get_app()
  File "/Users/antoniopace/message-in-a-bottle/venv/lib/python3.9/site-packages/flask_sqlalchemy/__init__.py", line 1042, in get_app
    raise RuntimeError(
RuntimeError: No application found. Either work inside a view function or push an application context. See http://flask-sqlalchemy.pocoo.org/contexts/.
[2021-10-24 17:08:59,272: INFO/MainProcess] Task monolith.background.send_message[a3ffe07c-d304-425f-ad20-ed0bd46627a4] received
[2021-10-24 17:08:59,285: ERROR/ForkPoolWorker-4] Task monolith.background.send_message[a3ffe07c-d304-425f-ad20-ed0bd46627a4] raised unexpected: RuntimeError('No application found. Either work inside a view function or push an application context. See http://flask-sqlalchemy.pocoo.org/contexts/.')
Traceback (most recent call last):
  File "/Users/antoniopace/message-in-a-bottle/venv/lib/python3.9/site-packages/sqlalchemy/util/_collections.py", line 1008, in __call__
    return self.registry[key]
KeyError: <greenlet.greenlet object at 0x7fe78bc0b7d0 (otid=0x7fe78ac4f700) current active started main>

During handling of the above exception, another exception occurred:

Traceback (most recent call last):
  File "/Users/antoniopace/message-in-a-bottle/venv/lib/python3.9/site-packages/celery/app/trace.py", line 450, in trace_task
    R = retval = fun(*args, **kwargs)
  File "/Users/antoniopace/message-in-a-bottle/venv/lib/python3.9/site-packages/celery/app/trace.py", line 731, in __protected_call__
    return self.run(*args, **kwargs)
  File "/Users/antoniopace/message-in-a-bottle/monolith/background.py", line 23, in send_message
    message.receiver= data['receiver']
  File "<string>", line 2, in add
  File "/Users/antoniopace/message-in-a-bottle/venv/lib/python3.9/site-packages/sqlalchemy/orm/scoping.py", line 24, in _proxied
    return self.registry()
  File "/Users/antoniopace/message-in-a-bottle/venv/lib/python3.9/site-packages/sqlalchemy/util/_collections.py", line 1010, in __call__
    return self.registry.setdefault(key, self.createfunc())
  File "/Users/antoniopace/message-in-a-bottle/venv/lib/python3.9/site-packages/sqlalchemy/orm/session.py", line 4172, in __call__
    return self.class_(**local_kw)
  File "/Users/antoniopace/message-in-a-bottle/venv/lib/python3.9/site-packages/flask_sqlalchemy/__init__.py", line 174, in __init__
    self.app = app = db.get_app()
  File "/Users/antoniopace/message-in-a-bottle/venv/lib/python3.9/site-packages/flask_sqlalchemy/__init__.py", line 1042, in get_app
    raise RuntimeError(
RuntimeError: No application found. Either work inside a view function or push an application context. See http://flask-sqlalchemy.pocoo.org/contexts/.
[2021-10-24 17:09:02,926: INFO/MainProcess] Task monolith.background.send_message[0ff5161c-9e49-4d20-8aa9-29bc75e866d5] received
[2021-10-24 17:09:02,940: ERROR/ForkPoolWorker-4] Task monolith.background.send_message[0ff5161c-9e49-4d20-8aa9-29bc75e866d5] raised unexpected: RuntimeError('No application found. Either work inside a view function or push an application context. See http://flask-sqlalchemy.pocoo.org/contexts/.')
Traceback (most recent call last):
  File "/Users/antoniopace/message-in-a-bottle/venv/lib/python3.9/site-packages/sqlalchemy/util/_collections.py", line 1008, in __call__
    return self.registry[key]
KeyError: <greenlet.greenlet object at 0x7fe78bc0b7d0 (otid=0x7fe78ac4f700) current active started main>

During handling of the above exception, another exception occurred:

Traceback (most recent call last):
  File "/Users/antoniopace/message-in-a-bottle/venv/lib/python3.9/site-packages/celery/app/trace.py", line 450, in trace_task
    R = retval = fun(*args, **kwargs)
  File "/Users/antoniopace/message-in-a-bottle/venv/lib/python3.9/site-packages/celery/app/trace.py", line 731, in __protected_call__
    return self.run(*args, **kwargs)
  File "/Users/antoniopace/message-in-a-bottle/monolith/background.py", line 23, in send_message
    message.receiver= data['receiver']
  File "<string>", line 2, in add
  File "/Users/antoniopace/message-in-a-bottle/venv/lib/python3.9/site-packages/sqlalchemy/orm/scoping.py", line 24, in _proxied
    return self.registry()
  File "/Users/antoniopace/message-in-a-bottle/venv/lib/python3.9/site-packages/sqlalchemy/util/_collections.py", line 1010, in __call__
    return self.registry.setdefault(key, self.createfunc())
  File "/Users/antoniopace/message-in-a-bottle/venv/lib/python3.9/site-packages/sqlalchemy/orm/session.py", line 4172, in __call__
    return self.class_(**local_kw)
  File "/Users/antoniopace/message-in-a-bottle/venv/lib/python3.9/site-packages/flask_sqlalchemy/__init__.py", line 174, in __init__
    self.app = app = db.get_app()
  File "/Users/antoniopace/message-in-a-bottle/venv/lib/python3.9/site-packages/flask_sqlalchemy/__init__.py", line 1042, in get_app
    raise RuntimeError(
RuntimeError: No application found. Either work inside a view function or push an application context. See http://flask-sqlalchemy.pocoo.org/contexts/.
[2021-10-24 17:09:04,822: INFO/MainProcess] Task monolith.background.send_message[ac763d06-a9db-495b-a295-e14196baefdf] received
[2021-10-24 17:09:04,836: ERROR/ForkPoolWorker-4] Task monolith.background.send_message[ac763d06-a9db-495b-a295-e14196baefdf] raised unexpected: RuntimeError('No application found. Either work inside a view function or push an application context. See http://flask-sqlalchemy.pocoo.org/contexts/.')
Traceback (most recent call last):
  File "/Users/antoniopace/message-in-a-bottle/venv/lib/python3.9/site-packages/sqlalchemy/util/_collections.py", line 1008, in __call__
    return self.registry[key]
KeyError: <greenlet.greenlet object at 0x7fe78bc0b7d0 (otid=0x7fe78ac4f700) current active started main>

During handling of the above exception, another exception occurred:

Traceback (most recent call last):
  File "/Users/antoniopace/message-in-a-bottle/venv/lib/python3.9/site-packages/celery/app/trace.py", line 450, in trace_task
    R = retval = fun(*args, **kwargs)
  File "/Users/antoniopace/message-in-a-bottle/venv/lib/python3.9/site-packages/celery/app/trace.py", line 731, in __protected_call__
    return self.run(*args, **kwargs)
  File "/Users/antoniopace/message-in-a-bottle/monolith/background.py", line 23, in send_message
    message.receiver= data['receiver']
  File "<string>", line 2, in add
  File "/Users/antoniopace/message-in-a-bottle/venv/lib/python3.9/site-packages/sqlalchemy/orm/scoping.py", line 24, in _proxied
    return self.registry()
  File "/Users/antoniopace/message-in-a-bottle/venv/lib/python3.9/site-packages/sqlalchemy/util/_collections.py", line 1010, in __call__
    return self.registry.setdefault(key, self.createfunc())
  File "/Users/antoniopace/message-in-a-bottle/venv/lib/python3.9/site-packages/sqlalchemy/orm/session.py", line 4172, in __call__
    return self.class_(**local_kw)
  File "/Users/antoniopace/message-in-a-bottle/venv/lib/python3.9/site-packages/flask_sqlalchemy/__init__.py", line 174, in __init__
    self.app = app = db.get_app()
  File "/Users/antoniopace/message-in-a-bottle/venv/lib/python3.9/site-packages/flask_sqlalchemy/__init__.py", line 1042, in get_app
    raise RuntimeError(
RuntimeError: No application found. Either work inside a view function or push an application context. See http://flask-sqlalchemy.pocoo.org/contexts/.
[2021-10-24 17:09:10,099: INFO/MainProcess] Task monolith.background.send_message[99f23d97-bc2a-4b60-90c0-db24cf52ee34] received
[2021-10-24 17:09:10,144: WARNING/ForkPoolWorker-6] <Message 70>
[2021-10-24 17:09:10,146: WARNING/ForkPoolWorker-6] 

[2021-10-24 17:09:10,154: INFO/ForkPoolWorker-6] Task monolith.background.send_message[99f23d97-bc2a-4b60-90c0-db24cf52ee34] succeeded in 0.050218601999972634s: []
[2021-10-24 17:09:42,040: INFO/MainProcess] Task monolith.background.send_message[5e117bbd-4640-42b0-800c-6bf6d7ca2533] received
[2021-10-24 17:09:42,067: WARNING/ForkPoolWorker-6] <Message 71>
[2021-10-24 17:09:42,068: WARNING/ForkPoolWorker-6] 

[2021-10-24 17:09:42,072: INFO/ForkPoolWorker-6] Task monolith.background.send_message[5e117bbd-4640-42b0-800c-6bf6d7ca2533] succeeded in 0.02797750799993537s: []
[2021-10-24 17:10:13,222: INFO/MainProcess] Task monolith.background.send_message[1e6e9e39-19d5-414f-a4ce-a5e7430cdbd6] received
[2021-10-24 17:10:13,237: WARNING/ForkPoolWorker-6] <Message 72>
[2021-10-24 17:10:13,238: WARNING/ForkPoolWorker-6] 

[2021-10-24 17:10:13,242: INFO/ForkPoolWorker-6] Task monolith.background.send_message[1e6e9e39-19d5-414f-a4ce-a5e7430cdbd6] succeeded in 0.015874223999958303s: []
[2021-10-24 17:10:14,597: INFO/MainProcess] Task monolith.background.send_message[55553523-dc0e-415c-8542-4463d38eda14] received
[2021-10-24 17:10:14,613: ERROR/ForkPoolWorker-4] Task monolith.background.send_message[55553523-dc0e-415c-8542-4463d38eda14] raised unexpected: RuntimeError('No application found. Either work inside a view function or push an application context. See http://flask-sqlalchemy.pocoo.org/contexts/.')
Traceback (most recent call last):
  File "/Users/antoniopace/message-in-a-bottle/venv/lib/python3.9/site-packages/sqlalchemy/util/_collections.py", line 1008, in __call__
    return self.registry[key]
KeyError: <greenlet.greenlet object at 0x7fe78bc0b7d0 (otid=0x7fe78ac4f700) current active started main>

During handling of the above exception, another exception occurred:

Traceback (most recent call last):
  File "/Users/antoniopace/message-in-a-bottle/venv/lib/python3.9/site-packages/celery/app/trace.py", line 450, in trace_task
    R = retval = fun(*args, **kwargs)
  File "/Users/antoniopace/message-in-a-bottle/venv/lib/python3.9/site-packages/celery/app/trace.py", line 731, in __protected_call__
    return self.run(*args, **kwargs)
  File "/Users/antoniopace/message-in-a-bottle/monolith/background.py", line 23, in send_message
    message.receiver= data['receiver']
  File "<string>", line 2, in add
  File "/Users/antoniopace/message-in-a-bottle/venv/lib/python3.9/site-packages/sqlalchemy/orm/scoping.py", line 24, in _proxied
    return self.registry()
  File "/Users/antoniopace/message-in-a-bottle/venv/lib/python3.9/site-packages/sqlalchemy/util/_collections.py", line 1010, in __call__
    return self.registry.setdefault(key, self.createfunc())
  File "/Users/antoniopace/message-in-a-bottle/venv/lib/python3.9/site-packages/sqlalchemy/orm/session.py", line 4172, in __call__
    return self.class_(**local_kw)
  File "/Users/antoniopace/message-in-a-bottle/venv/lib/python3.9/site-packages/flask_sqlalchemy/__init__.py", line 174, in __init__
    self.app = app = db.get_app()
  File "/Users/antoniopace/message-in-a-bottle/venv/lib/python3.9/site-packages/flask_sqlalchemy/__init__.py", line 1042, in get_app
    raise RuntimeError(
RuntimeError: No application found. Either work inside a view function or push an application context. See http://flask-sqlalchemy.pocoo.org/contexts/.
[2021-10-24 17:10:15,549: INFO/MainProcess] Task monolith.background.send_message[fde8a73e-04e2-46e8-919e-378ffb4c622c] received
[2021-10-24 17:10:15,569: ERROR/ForkPoolWorker-4] Task monolith.background.send_message[fde8a73e-04e2-46e8-919e-378ffb4c622c] raised unexpected: RuntimeError('No application found. Either work inside a view function or push an application context. See http://flask-sqlalchemy.pocoo.org/contexts/.')
Traceback (most recent call last):
  File "/Users/antoniopace/message-in-a-bottle/venv/lib/python3.9/site-packages/sqlalchemy/util/_collections.py", line 1008, in __call__
    return self.registry[key]
KeyError: <greenlet.greenlet object at 0x7fe78bc0b7d0 (otid=0x7fe78ac4f700) current active started main>

During handling of the above exception, another exception occurred:

Traceback (most recent call last):
  File "/Users/antoniopace/message-in-a-bottle/venv/lib/python3.9/site-packages/celery/app/trace.py", line 450, in trace_task
    R = retval = fun(*args, **kwargs)
  File "/Users/antoniopace/message-in-a-bottle/venv/lib/python3.9/site-packages/celery/app/trace.py", line 731, in __protected_call__
    return self.run(*args, **kwargs)
  File "/Users/antoniopace/message-in-a-bottle/monolith/background.py", line 23, in send_message
    message.receiver= data['receiver']
  File "<string>", line 2, in add
  File "/Users/antoniopace/message-in-a-bottle/venv/lib/python3.9/site-packages/sqlalchemy/orm/scoping.py", line 24, in _proxied
    return self.registry()
  File "/Users/antoniopace/message-in-a-bottle/venv/lib/python3.9/site-packages/sqlalchemy/util/_collections.py", line 1010, in __call__
    return self.registry.setdefault(key, self.createfunc())
  File "/Users/antoniopace/message-in-a-bottle/venv/lib/python3.9/site-packages/sqlalchemy/orm/session.py", line 4172, in __call__
    return self.class_(**local_kw)
  File "/Users/antoniopace/message-in-a-bottle/venv/lib/python3.9/site-packages/flask_sqlalchemy/__init__.py", line 174, in __init__
    self.app = app = db.get_app()
  File "/Users/antoniopace/message-in-a-bottle/venv/lib/python3.9/site-packages/flask_sqlalchemy/__init__.py", line 1042, in get_app
    raise RuntimeError(
RuntimeError: No application found. Either work inside a view function or push an application context. See http://flask-sqlalchemy.pocoo.org/contexts/.
[2021-10-24 17:10:32,167: INFO/MainProcess] Task monolith.background.send_message[4cc0f3ea-8fb2-424d-b60a-1dfefc5bf965] received
[2021-10-24 17:10:32,187: WARNING/ForkPoolWorker-6] <Message 73>
[2021-10-24 17:10:32,187: WARNING/ForkPoolWorker-6] 

[2021-10-24 17:10:32,192: INFO/ForkPoolWorker-6] Task monolith.background.send_message[4cc0f3ea-8fb2-424d-b60a-1dfefc5bf965] succeeded in 0.018138797999995404s: []
[2021-10-24 17:10:32,746: INFO/MainProcess] Task monolith.background.send_message[fbeae7f5-34ce-4a15-acf6-c9eac9c53d8c] received
[2021-10-24 17:10:32,759: ERROR/ForkPoolWorker-4] Task monolith.background.send_message[fbeae7f5-34ce-4a15-acf6-c9eac9c53d8c] raised unexpected: RuntimeError('No application found. Either work inside a view function or push an application context. See http://flask-sqlalchemy.pocoo.org/contexts/.')
Traceback (most recent call last):
  File "/Users/antoniopace/message-in-a-bottle/venv/lib/python3.9/site-packages/sqlalchemy/util/_collections.py", line 1008, in __call__
    return self.registry[key]
KeyError: <greenlet.greenlet object at 0x7fe78bc0b7d0 (otid=0x7fe78ac4f700) current active started main>

During handling of the above exception, another exception occurred:

Traceback (most recent call last):
  File "/Users/antoniopace/message-in-a-bottle/venv/lib/python3.9/site-packages/celery/app/trace.py", line 450, in trace_task
    R = retval = fun(*args, **kwargs)
  File "/Users/antoniopace/message-in-a-bottle/venv/lib/python3.9/site-packages/celery/app/trace.py", line 731, in __protected_call__
    return self.run(*args, **kwargs)
  File "/Users/antoniopace/message-in-a-bottle/monolith/background.py", line 23, in send_message
    message.receiver= data['receiver']
  File "<string>", line 2, in add
  File "/Users/antoniopace/message-in-a-bottle/venv/lib/python3.9/site-packages/sqlalchemy/orm/scoping.py", line 24, in _proxied
    return self.registry()
  File "/Users/antoniopace/message-in-a-bottle/venv/lib/python3.9/site-packages/sqlalchemy/util/_collections.py", line 1010, in __call__
    return self.registry.setdefault(key, self.createfunc())
  File "/Users/antoniopace/message-in-a-bottle/venv/lib/python3.9/site-packages/sqlalchemy/orm/session.py", line 4172, in __call__
    return self.class_(**local_kw)
  File "/Users/antoniopace/message-in-a-bottle/venv/lib/python3.9/site-packages/flask_sqlalchemy/__init__.py", line 174, in __init__
    self.app = app = db.get_app()
  File "/Users/antoniopace/message-in-a-bottle/venv/lib/python3.9/site-packages/flask_sqlalchemy/__init__.py", line 1042, in get_app
    raise RuntimeError(
RuntimeError: No application found. Either work inside a view function or push an application context. See http://flask-sqlalchemy.pocoo.org/contexts/.
[2021-10-24 17:10:33,232: INFO/MainProcess] Task monolith.background.send_message[08f6a3f3-20fc-4f1b-9931-b68ba6853504] received
[2021-10-24 17:10:33,249: ERROR/ForkPoolWorker-4] Task monolith.background.send_message[08f6a3f3-20fc-4f1b-9931-b68ba6853504] raised unexpected: RuntimeError('No application found. Either work inside a view function or push an application context. See http://flask-sqlalchemy.pocoo.org/contexts/.')
Traceback (most recent call last):
  File "/Users/antoniopace/message-in-a-bottle/venv/lib/python3.9/site-packages/sqlalchemy/util/_collections.py", line 1008, in __call__
    return self.registry[key]
KeyError: <greenlet.greenlet object at 0x7fe78bc0b7d0 (otid=0x7fe78ac4f700) current active started main>

During handling of the above exception, another exception occurred:

Traceback (most recent call last):
  File "/Users/antoniopace/message-in-a-bottle/venv/lib/python3.9/site-packages/celery/app/trace.py", line 450, in trace_task
    R = retval = fun(*args, **kwargs)
  File "/Users/antoniopace/message-in-a-bottle/venv/lib/python3.9/site-packages/celery/app/trace.py", line 731, in __protected_call__
    return self.run(*args, **kwargs)
  File "/Users/antoniopace/message-in-a-bottle/monolith/background.py", line 23, in send_message
    message.receiver= data['receiver']
  File "<string>", line 2, in add
  File "/Users/antoniopace/message-in-a-bottle/venv/lib/python3.9/site-packages/sqlalchemy/orm/scoping.py", line 24, in _proxied
    return self.registry()
  File "/Users/antoniopace/message-in-a-bottle/venv/lib/python3.9/site-packages/sqlalchemy/util/_collections.py", line 1010, in __call__
    return self.registry.setdefault(key, self.createfunc())
  File "/Users/antoniopace/message-in-a-bottle/venv/lib/python3.9/site-packages/sqlalchemy/orm/session.py", line 4172, in __call__
    return self.class_(**local_kw)
  File "/Users/antoniopace/message-in-a-bottle/venv/lib/python3.9/site-packages/flask_sqlalchemy/__init__.py", line 174, in __init__
    self.app = app = db.get_app()
  File "/Users/antoniopace/message-in-a-bottle/venv/lib/python3.9/site-packages/flask_sqlalchemy/__init__.py", line 1042, in get_app
    raise RuntimeError(
RuntimeError: No application found. Either work inside a view function or push an application context. See http://flask-sqlalchemy.pocoo.org/contexts/.
[2021-10-24 17:10:33,716: INFO/MainProcess] Task monolith.background.send_message[5c0710cc-63d1-4aac-b354-d45d792105f5] received
[2021-10-24 17:10:33,736: WARNING/ForkPoolWorker-6] <Message 74>
[2021-10-24 17:10:33,737: WARNING/ForkPoolWorker-6] 

[2021-10-24 17:10:33,743: INFO/ForkPoolWorker-6] Task monolith.background.send_message[5c0710cc-63d1-4aac-b354-d45d792105f5] succeeded in 0.025592340999992302s: []
[2021-10-24 17:10:36,460: INFO/MainProcess] Task monolith.background.send_message[dce34220-a499-4591-8ddb-c6f9757433db] received
[2021-10-24 17:10:36,479: WARNING/ForkPoolWorker-6] <Message 75>
[2021-10-24 17:10:36,480: WARNING/ForkPoolWorker-6] 

[2021-10-24 17:10:36,483: INFO/ForkPoolWorker-6] Task monolith.background.send_message[dce34220-a499-4591-8ddb-c6f9757433db] succeeded in 0.021568144999946526s: []
[2021-10-24 17:10:37,120: INFO/MainProcess] Task monolith.background.send_message[4da1505b-6759-4525-adcf-2f49772b58d0] received
[2021-10-24 17:10:37,143: ERROR/ForkPoolWorker-4] Task monolith.background.send_message[4da1505b-6759-4525-adcf-2f49772b58d0] raised unexpected: RuntimeError('No application found. Either work inside a view function or push an application context. See http://flask-sqlalchemy.pocoo.org/contexts/.')
Traceback (most recent call last):
  File "/Users/antoniopace/message-in-a-bottle/venv/lib/python3.9/site-packages/sqlalchemy/util/_collections.py", line 1008, in __call__
    return self.registry[key]
KeyError: <greenlet.greenlet object at 0x7fe78bc0b7d0 (otid=0x7fe78ac4f700) current active started main>

During handling of the above exception, another exception occurred:

Traceback (most recent call last):
  File "/Users/antoniopace/message-in-a-bottle/venv/lib/python3.9/site-packages/celery/app/trace.py", line 450, in trace_task
    R = retval = fun(*args, **kwargs)
  File "/Users/antoniopace/message-in-a-bottle/venv/lib/python3.9/site-packages/celery/app/trace.py", line 731, in __protected_call__
    return self.run(*args, **kwargs)
  File "/Users/antoniopace/message-in-a-bottle/monolith/background.py", line 23, in send_message
    message.receiver= data['receiver']
  File "<string>", line 2, in add
  File "/Users/antoniopace/message-in-a-bottle/venv/lib/python3.9/site-packages/sqlalchemy/orm/scoping.py", line 24, in _proxied
    return self.registry()
  File "/Users/antoniopace/message-in-a-bottle/venv/lib/python3.9/site-packages/sqlalchemy/util/_collections.py", line 1010, in __call__
    return self.registry.setdefault(key, self.createfunc())
  File "/Users/antoniopace/message-in-a-bottle/venv/lib/python3.9/site-packages/sqlalchemy/orm/session.py", line 4172, in __call__
    return self.class_(**local_kw)
  File "/Users/antoniopace/message-in-a-bottle/venv/lib/python3.9/site-packages/flask_sqlalchemy/__init__.py", line 174, in __init__
    self.app = app = db.get_app()
  File "/Users/antoniopace/message-in-a-bottle/venv/lib/python3.9/site-packages/flask_sqlalchemy/__init__.py", line 1042, in get_app
    raise RuntimeError(
RuntimeError: No application found. Either work inside a view function or push an application context. See http://flask-sqlalchemy.pocoo.org/contexts/.
[2021-10-24 17:10:38,385: INFO/MainProcess] Task monolith.background.send_message[4c89672e-fba6-4d50-8554-26a25546e9bd] received
[2021-10-24 17:10:38,403: WARNING/ForkPoolWorker-6] <Message 76>
[2021-10-24 17:10:38,404: WARNING/ForkPoolWorker-6] 

[2021-10-24 17:10:38,407: INFO/ForkPoolWorker-6] Task monolith.background.send_message[4c89672e-fba6-4d50-8554-26a25546e9bd] succeeded in 0.0214115320000019s: []
[2021-10-24 17:10:39,012: INFO/MainProcess] Task monolith.background.send_message[e0e3bef5-79ef-4102-a382-d675a2f12f07] received
[2021-10-24 17:10:39,025: ERROR/ForkPoolWorker-4] Task monolith.background.send_message[e0e3bef5-79ef-4102-a382-d675a2f12f07] raised unexpected: RuntimeError('No application found. Either work inside a view function or push an application context. See http://flask-sqlalchemy.pocoo.org/contexts/.')
Traceback (most recent call last):
  File "/Users/antoniopace/message-in-a-bottle/venv/lib/python3.9/site-packages/sqlalchemy/util/_collections.py", line 1008, in __call__
    return self.registry[key]
KeyError: <greenlet.greenlet object at 0x7fe78bc0b7d0 (otid=0x7fe78ac4f700) current active started main>

During handling of the above exception, another exception occurred:

Traceback (most recent call last):
  File "/Users/antoniopace/message-in-a-bottle/venv/lib/python3.9/site-packages/celery/app/trace.py", line 450, in trace_task
    R = retval = fun(*args, **kwargs)
  File "/Users/antoniopace/message-in-a-bottle/venv/lib/python3.9/site-packages/celery/app/trace.py", line 731, in __protected_call__
    return self.run(*args, **kwargs)
  File "/Users/antoniopace/message-in-a-bottle/monolith/background.py", line 23, in send_message
    message.receiver= data['receiver']
  File "<string>", line 2, in add
  File "/Users/antoniopace/message-in-a-bottle/venv/lib/python3.9/site-packages/sqlalchemy/orm/scoping.py", line 24, in _proxied
    return self.registry()
  File "/Users/antoniopace/message-in-a-bottle/venv/lib/python3.9/site-packages/sqlalchemy/util/_collections.py", line 1010, in __call__
    return self.registry.setdefault(key, self.createfunc())
  File "/Users/antoniopace/message-in-a-bottle/venv/lib/python3.9/site-packages/sqlalchemy/orm/session.py", line 4172, in __call__
    return self.class_(**local_kw)
  File "/Users/antoniopace/message-in-a-bottle/venv/lib/python3.9/site-packages/flask_sqlalchemy/__init__.py", line 174, in __init__
    self.app = app = db.get_app()
  File "/Users/antoniopace/message-in-a-bottle/venv/lib/python3.9/site-packages/flask_sqlalchemy/__init__.py", line 1042, in get_app
    raise RuntimeError(
RuntimeError: No application found. Either work inside a view function or push an application context. See http://flask-sqlalchemy.pocoo.org/contexts/.
[2021-10-24 17:10:40,200: INFO/MainProcess] Task monolith.background.send_message[0ed7a590-4b0e-49d0-af06-64a222b35af6] received
[2021-10-24 17:10:40,219: WARNING/ForkPoolWorker-6] <Message 77>
[2021-10-24 17:10:40,219: WARNING/ForkPoolWorker-6] 

[2021-10-24 17:10:40,222: INFO/ForkPoolWorker-6] Task monolith.background.send_message[0ed7a590-4b0e-49d0-af06-64a222b35af6] succeeded in 0.021171244000015577s: []
[2021-10-24 17:10:40,809: INFO/MainProcess] Task monolith.background.send_message[987593c8-4f2b-4140-83ba-6620f1f892a9] received
[2021-10-24 17:10:40,826: ERROR/ForkPoolWorker-4] Task monolith.background.send_message[987593c8-4f2b-4140-83ba-6620f1f892a9] raised unexpected: RuntimeError('No application found. Either work inside a view function or push an application context. See http://flask-sqlalchemy.pocoo.org/contexts/.')
Traceback (most recent call last):
  File "/Users/antoniopace/message-in-a-bottle/venv/lib/python3.9/site-packages/sqlalchemy/util/_collections.py", line 1008, in __call__
    return self.registry[key]
KeyError: <greenlet.greenlet object at 0x7fe78bc0b7d0 (otid=0x7fe78ac4f700) current active started main>

During handling of the above exception, another exception occurred:

Traceback (most recent call last):
  File "/Users/antoniopace/message-in-a-bottle/venv/lib/python3.9/site-packages/celery/app/trace.py", line 450, in trace_task
    R = retval = fun(*args, **kwargs)
  File "/Users/antoniopace/message-in-a-bottle/venv/lib/python3.9/site-packages/celery/app/trace.py", line 731, in __protected_call__
    return self.run(*args, **kwargs)
  File "/Users/antoniopace/message-in-a-bottle/monolith/background.py", line 23, in send_message
    message.receiver= data['receiver']
  File "<string>", line 2, in add
  File "/Users/antoniopace/message-in-a-bottle/venv/lib/python3.9/site-packages/sqlalchemy/orm/scoping.py", line 24, in _proxied
    return self.registry()
  File "/Users/antoniopace/message-in-a-bottle/venv/lib/python3.9/site-packages/sqlalchemy/util/_collections.py", line 1010, in __call__
    return self.registry.setdefault(key, self.createfunc())
  File "/Users/antoniopace/message-in-a-bottle/venv/lib/python3.9/site-packages/sqlalchemy/orm/session.py", line 4172, in __call__
    return self.class_(**local_kw)
  File "/Users/antoniopace/message-in-a-bottle/venv/lib/python3.9/site-packages/flask_sqlalchemy/__init__.py", line 174, in __init__
    self.app = app = db.get_app()
  File "/Users/antoniopace/message-in-a-bottle/venv/lib/python3.9/site-packages/flask_sqlalchemy/__init__.py", line 1042, in get_app
    raise RuntimeError(
RuntimeError: No application found. Either work inside a view function or push an application context. See http://flask-sqlalchemy.pocoo.org/contexts/.
[2021-10-24 17:10:42,184: INFO/MainProcess] Task monolith.background.send_message[3cea8337-aec6-4671-bb36-7e2890606bea] received
[2021-10-24 17:10:42,203: WARNING/ForkPoolWorker-6] <Message 78>
[2021-10-24 17:10:42,204: WARNING/ForkPoolWorker-6] 

[2021-10-24 17:10:42,210: INFO/ForkPoolWorker-6] Task monolith.background.send_message[3cea8337-aec6-4671-bb36-7e2890606bea] succeeded in 0.02440774500007592s: []
[2021-10-24 17:11:56,294: INFO/MainProcess] Task monolith.background.send_message[4657f472-c60d-4f4b-99bd-836198e94efb] received
[2021-10-24 17:11:56,310: ERROR/ForkPoolWorker-4] Task monolith.background.send_message[4657f472-c60d-4f4b-99bd-836198e94efb] raised unexpected: RuntimeError('No application found. Either work inside a view function or push an application context. See http://flask-sqlalchemy.pocoo.org/contexts/.')
Traceback (most recent call last):
  File "/Users/antoniopace/message-in-a-bottle/venv/lib/python3.9/site-packages/sqlalchemy/util/_collections.py", line 1008, in __call__
    return self.registry[key]
KeyError: <greenlet.greenlet object at 0x7fe78bc0b7d0 (otid=0x7fe78ac4f700) current active started main>

During handling of the above exception, another exception occurred:

Traceback (most recent call last):
  File "/Users/antoniopace/message-in-a-bottle/venv/lib/python3.9/site-packages/celery/app/trace.py", line 450, in trace_task
    R = retval = fun(*args, **kwargs)
  File "/Users/antoniopace/message-in-a-bottle/venv/lib/python3.9/site-packages/celery/app/trace.py", line 731, in __protected_call__
    return self.run(*args, **kwargs)
  File "/Users/antoniopace/message-in-a-bottle/monolith/background.py", line 23, in send_message
    message.receiver= data['receiver']
  File "<string>", line 2, in add
  File "/Users/antoniopace/message-in-a-bottle/venv/lib/python3.9/site-packages/sqlalchemy/orm/scoping.py", line 24, in _proxied
    return self.registry()
  File "/Users/antoniopace/message-in-a-bottle/venv/lib/python3.9/site-packages/sqlalchemy/util/_collections.py", line 1010, in __call__
    return self.registry.setdefault(key, self.createfunc())
  File "/Users/antoniopace/message-in-a-bottle/venv/lib/python3.9/site-packages/sqlalchemy/orm/session.py", line 4172, in __call__
    return self.class_(**local_kw)
  File "/Users/antoniopace/message-in-a-bottle/venv/lib/python3.9/site-packages/flask_sqlalchemy/__init__.py", line 174, in __init__
    self.app = app = db.get_app()
  File "/Users/antoniopace/message-in-a-bottle/venv/lib/python3.9/site-packages/flask_sqlalchemy/__init__.py", line 1042, in get_app
    raise RuntimeError(
RuntimeError: No application found. Either work inside a view function or push an application context. See http://flask-sqlalchemy.pocoo.org/contexts/.
[2021-10-24 17:12:00,755: INFO/MainProcess] Task monolith.background.send_message[07b38fdd-0ef7-4d04-8445-6c77d7f958a6] received
[2021-10-24 17:12:00,773: ERROR/ForkPoolWorker-4] Task monolith.background.send_message[07b38fdd-0ef7-4d04-8445-6c77d7f958a6] raised unexpected: RuntimeError('No application found. Either work inside a view function or push an application context. See http://flask-sqlalchemy.pocoo.org/contexts/.')
Traceback (most recent call last):
  File "/Users/antoniopace/message-in-a-bottle/venv/lib/python3.9/site-packages/sqlalchemy/util/_collections.py", line 1008, in __call__
    return self.registry[key]
KeyError: <greenlet.greenlet object at 0x7fe78bc0b7d0 (otid=0x7fe78ac4f700) current active started main>

During handling of the above exception, another exception occurred:

Traceback (most recent call last):
  File "/Users/antoniopace/message-in-a-bottle/venv/lib/python3.9/site-packages/celery/app/trace.py", line 450, in trace_task
    R = retval = fun(*args, **kwargs)
  File "/Users/antoniopace/message-in-a-bottle/venv/lib/python3.9/site-packages/celery/app/trace.py", line 731, in __protected_call__
    return self.run(*args, **kwargs)
  File "/Users/antoniopace/message-in-a-bottle/monolith/background.py", line 23, in send_message
    message.receiver= data['receiver']
  File "<string>", line 2, in add
  File "/Users/antoniopace/message-in-a-bottle/venv/lib/python3.9/site-packages/sqlalchemy/orm/scoping.py", line 24, in _proxied
    return self.registry()
  File "/Users/antoniopace/message-in-a-bottle/venv/lib/python3.9/site-packages/sqlalchemy/util/_collections.py", line 1010, in __call__
    return self.registry.setdefault(key, self.createfunc())
  File "/Users/antoniopace/message-in-a-bottle/venv/lib/python3.9/site-packages/sqlalchemy/orm/session.py", line 4172, in __call__
    return self.class_(**local_kw)
  File "/Users/antoniopace/message-in-a-bottle/venv/lib/python3.9/site-packages/flask_sqlalchemy/__init__.py", line 174, in __init__
    self.app = app = db.get_app()
  File "/Users/antoniopace/message-in-a-bottle/venv/lib/python3.9/site-packages/flask_sqlalchemy/__init__.py", line 1042, in get_app
    raise RuntimeError(
RuntimeError: No application found. Either work inside a view function or push an application context. See http://flask-sqlalchemy.pocoo.org/contexts/.
[2021-10-24 17:12:02,130: INFO/MainProcess] Task monolith.background.send_message[fecf1789-b2d2-49b5-a594-379aaea09bcc] received
[2021-10-24 17:12:02,149: WARNING/ForkPoolWorker-6] <Message 79>
[2021-10-24 17:12:02,149: WARNING/ForkPoolWorker-6] 

[2021-10-24 17:12:02,152: INFO/ForkPoolWorker-6] Task monolith.background.send_message[fecf1789-b2d2-49b5-a594-379aaea09bcc] succeeded in 0.019843435999973735s: []
[2021-10-24 17:12:04,455: INFO/MainProcess] Task monolith.background.send_message[ac7ba7fa-a597-4ecc-9e2e-f6b9e178048d] received
[2021-10-24 17:12:04,470: ERROR/ForkPoolWorker-4] Task monolith.background.send_message[ac7ba7fa-a597-4ecc-9e2e-f6b9e178048d] raised unexpected: RuntimeError('No application found. Either work inside a view function or push an application context. See http://flask-sqlalchemy.pocoo.org/contexts/.')
Traceback (most recent call last):
  File "/Users/antoniopace/message-in-a-bottle/venv/lib/python3.9/site-packages/sqlalchemy/util/_collections.py", line 1008, in __call__
    return self.registry[key]
KeyError: <greenlet.greenlet object at 0x7fe78bc0b7d0 (otid=0x7fe78ac4f700) current active started main>

During handling of the above exception, another exception occurred:

Traceback (most recent call last):
  File "/Users/antoniopace/message-in-a-bottle/venv/lib/python3.9/site-packages/celery/app/trace.py", line 450, in trace_task
    R = retval = fun(*args, **kwargs)
  File "/Users/antoniopace/message-in-a-bottle/venv/lib/python3.9/site-packages/celery/app/trace.py", line 731, in __protected_call__
    return self.run(*args, **kwargs)
  File "/Users/antoniopace/message-in-a-bottle/monolith/background.py", line 23, in send_message
    message.receiver= data['receiver']
  File "<string>", line 2, in add
  File "/Users/antoniopace/message-in-a-bottle/venv/lib/python3.9/site-packages/sqlalchemy/orm/scoping.py", line 24, in _proxied
    return self.registry()
  File "/Users/antoniopace/message-in-a-bottle/venv/lib/python3.9/site-packages/sqlalchemy/util/_collections.py", line 1010, in __call__
    return self.registry.setdefault(key, self.createfunc())
  File "/Users/antoniopace/message-in-a-bottle/venv/lib/python3.9/site-packages/sqlalchemy/orm/session.py", line 4172, in __call__
    return self.class_(**local_kw)
  File "/Users/antoniopace/message-in-a-bottle/venv/lib/python3.9/site-packages/flask_sqlalchemy/__init__.py", line 174, in __init__
    self.app = app = db.get_app()
  File "/Users/antoniopace/message-in-a-bottle/venv/lib/python3.9/site-packages/flask_sqlalchemy/__init__.py", line 1042, in get_app
    raise RuntimeError(
RuntimeError: No application found. Either work inside a view function or push an application context. See http://flask-sqlalchemy.pocoo.org/contexts/.
[2021-10-24 17:12:16,939: INFO/MainProcess] Task monolith.background.send_message[2637e31d-8b62-4995-94d6-e14230a2248d] received
[2021-10-24 17:12:16,952: WARNING/ForkPoolWorker-6] <Message 80>
[2021-10-24 17:12:16,952: WARNING/ForkPoolWorker-6] 

[2021-10-24 17:12:16,956: INFO/ForkPoolWorker-6] Task monolith.background.send_message[2637e31d-8b62-4995-94d6-e14230a2248d] succeeded in 0.015500989000088339s: []
[2021-10-24 17:12:19,552: INFO/MainProcess] Task monolith.background.send_message[c96f0046-5edd-4720-b93a-6ab0151c5804] received
[2021-10-24 17:12:19,564: ERROR/ForkPoolWorker-4] Task monolith.background.send_message[c96f0046-5edd-4720-b93a-6ab0151c5804] raised unexpected: RuntimeError('No application found. Either work inside a view function or push an application context. See http://flask-sqlalchemy.pocoo.org/contexts/.')
Traceback (most recent call last):
  File "/Users/antoniopace/message-in-a-bottle/venv/lib/python3.9/site-packages/sqlalchemy/util/_collections.py", line 1008, in __call__
    return self.registry[key]
KeyError: <greenlet.greenlet object at 0x7fe78bc0b7d0 (otid=0x7fe78ac4f700) current active started main>

During handling of the above exception, another exception occurred:

Traceback (most recent call last):
  File "/Users/antoniopace/message-in-a-bottle/venv/lib/python3.9/site-packages/celery/app/trace.py", line 450, in trace_task
    R = retval = fun(*args, **kwargs)
  File "/Users/antoniopace/message-in-a-bottle/venv/lib/python3.9/site-packages/celery/app/trace.py", line 731, in __protected_call__
    return self.run(*args, **kwargs)
  File "/Users/antoniopace/message-in-a-bottle/monolith/background.py", line 23, in send_message
    message.receiver= data['receiver']
  File "<string>", line 2, in add
  File "/Users/antoniopace/message-in-a-bottle/venv/lib/python3.9/site-packages/sqlalchemy/orm/scoping.py", line 24, in _proxied
    return self.registry()
  File "/Users/antoniopace/message-in-a-bottle/venv/lib/python3.9/site-packages/sqlalchemy/util/_collections.py", line 1010, in __call__
    return self.registry.setdefault(key, self.createfunc())
  File "/Users/antoniopace/message-in-a-bottle/venv/lib/python3.9/site-packages/sqlalchemy/orm/session.py", line 4172, in __call__
    return self.class_(**local_kw)
  File "/Users/antoniopace/message-in-a-bottle/venv/lib/python3.9/site-packages/flask_sqlalchemy/__init__.py", line 174, in __init__
    self.app = app = db.get_app()
  File "/Users/antoniopace/message-in-a-bottle/venv/lib/python3.9/site-packages/flask_sqlalchemy/__init__.py", line 1042, in get_app
    raise RuntimeError(
RuntimeError: No application found. Either work inside a view function or push an application context. See http://flask-sqlalchemy.pocoo.org/contexts/.
[2021-10-24 17:12:21,236: INFO/MainProcess] Task monolith.background.send_message[b4d1df1a-d9ad-4a4e-9b46-cfead4505123] received
[2021-10-24 17:12:21,248: ERROR/ForkPoolWorker-4] Task monolith.background.send_message[b4d1df1a-d9ad-4a4e-9b46-cfead4505123] raised unexpected: RuntimeError('No application found. Either work inside a view function or push an application context. See http://flask-sqlalchemy.pocoo.org/contexts/.')
Traceback (most recent call last):
  File "/Users/antoniopace/message-in-a-bottle/venv/lib/python3.9/site-packages/sqlalchemy/util/_collections.py", line 1008, in __call__
    return self.registry[key]
KeyError: <greenlet.greenlet object at 0x7fe78bc0b7d0 (otid=0x7fe78ac4f700) current active started main>

During handling of the above exception, another exception occurred:

Traceback (most recent call last):
  File "/Users/antoniopace/message-in-a-bottle/venv/lib/python3.9/site-packages/celery/app/trace.py", line 450, in trace_task
    R = retval = fun(*args, **kwargs)
  File "/Users/antoniopace/message-in-a-bottle/venv/lib/python3.9/site-packages/celery/app/trace.py", line 731, in __protected_call__
    return self.run(*args, **kwargs)
  File "/Users/antoniopace/message-in-a-bottle/monolith/background.py", line 23, in send_message
    message.receiver= data['receiver']
  File "<string>", line 2, in add
  File "/Users/antoniopace/message-in-a-bottle/venv/lib/python3.9/site-packages/sqlalchemy/orm/scoping.py", line 24, in _proxied
    return self.registry()
  File "/Users/antoniopace/message-in-a-bottle/venv/lib/python3.9/site-packages/sqlalchemy/util/_collections.py", line 1010, in __call__
    return self.registry.setdefault(key, self.createfunc())
  File "/Users/antoniopace/message-in-a-bottle/venv/lib/python3.9/site-packages/sqlalchemy/orm/session.py", line 4172, in __call__
    return self.class_(**local_kw)
  File "/Users/antoniopace/message-in-a-bottle/venv/lib/python3.9/site-packages/flask_sqlalchemy/__init__.py", line 174, in __init__
    self.app = app = db.get_app()
  File "/Users/antoniopace/message-in-a-bottle/venv/lib/python3.9/site-packages/flask_sqlalchemy/__init__.py", line 1042, in get_app
    raise RuntimeError(
RuntimeError: No application found. Either work inside a view function or push an application context. See http://flask-sqlalchemy.pocoo.org/contexts/.
[2021-10-24 17:12:23,068: INFO/MainProcess] Task monolith.background.send_message[f7586b48-7a44-4522-9281-60b24a2d33df] received
[2021-10-24 17:12:23,088: WARNING/ForkPoolWorker-6] <Message 81>
[2021-10-24 17:12:23,088: WARNING/ForkPoolWorker-6] 

[2021-10-24 17:12:23,092: INFO/ForkPoolWorker-6] Task monolith.background.send_message[f7586b48-7a44-4522-9281-60b24a2d33df] succeeded in 0.02216635700006009s: []
[2021-10-24 17:12:24,202: INFO/MainProcess] Task monolith.background.send_message[a9fe0fe5-5faf-4d9e-93d1-7e8cd72344b7] received
[2021-10-24 17:12:24,216: ERROR/ForkPoolWorker-4] Task monolith.background.send_message[a9fe0fe5-5faf-4d9e-93d1-7e8cd72344b7] raised unexpected: RuntimeError('No application found. Either work inside a view function or push an application context. See http://flask-sqlalchemy.pocoo.org/contexts/.')
Traceback (most recent call last):
  File "/Users/antoniopace/message-in-a-bottle/venv/lib/python3.9/site-packages/sqlalchemy/util/_collections.py", line 1008, in __call__
    return self.registry[key]
KeyError: <greenlet.greenlet object at 0x7fe78bc0b7d0 (otid=0x7fe78ac4f700) current active started main>

During handling of the above exception, another exception occurred:

Traceback (most recent call last):
  File "/Users/antoniopace/message-in-a-bottle/venv/lib/python3.9/site-packages/celery/app/trace.py", line 450, in trace_task
    R = retval = fun(*args, **kwargs)
  File "/Users/antoniopace/message-in-a-bottle/venv/lib/python3.9/site-packages/celery/app/trace.py", line 731, in __protected_call__
    return self.run(*args, **kwargs)
  File "/Users/antoniopace/message-in-a-bottle/monolith/background.py", line 23, in send_message
    message.receiver= data['receiver']
  File "<string>", line 2, in add
  File "/Users/antoniopace/message-in-a-bottle/venv/lib/python3.9/site-packages/sqlalchemy/orm/scoping.py", line 24, in _proxied
    return self.registry()
  File "/Users/antoniopace/message-in-a-bottle/venv/lib/python3.9/site-packages/sqlalchemy/util/_collections.py", line 1010, in __call__
    return self.registry.setdefault(key, self.createfunc())
  File "/Users/antoniopace/message-in-a-bottle/venv/lib/python3.9/site-packages/sqlalchemy/orm/session.py", line 4172, in __call__
    return self.class_(**local_kw)
  File "/Users/antoniopace/message-in-a-bottle/venv/lib/python3.9/site-packages/flask_sqlalchemy/__init__.py", line 174, in __init__
    self.app = app = db.get_app()
  File "/Users/antoniopace/message-in-a-bottle/venv/lib/python3.9/site-packages/flask_sqlalchemy/__init__.py", line 1042, in get_app
    raise RuntimeError(
RuntimeError: No application found. Either work inside a view function or push an application context. See http://flask-sqlalchemy.pocoo.org/contexts/.
[2021-10-24 17:12:26,230: INFO/MainProcess] Task monolith.background.send_message[34e79ade-d72a-40b7-a415-e4e96bbf84d2] received
[2021-10-24 17:12:26,244: ERROR/ForkPoolWorker-4] Task monolith.background.send_message[34e79ade-d72a-40b7-a415-e4e96bbf84d2] raised unexpected: RuntimeError('No application found. Either work inside a view function or push an application context. See http://flask-sqlalchemy.pocoo.org/contexts/.')
Traceback (most recent call last):
  File "/Users/antoniopace/message-in-a-bottle/venv/lib/python3.9/site-packages/sqlalchemy/util/_collections.py", line 1008, in __call__
    return self.registry[key]
KeyError: <greenlet.greenlet object at 0x7fe78bc0b7d0 (otid=0x7fe78ac4f700) current active started main>

During handling of the above exception, another exception occurred:

Traceback (most recent call last):
  File "/Users/antoniopace/message-in-a-bottle/venv/lib/python3.9/site-packages/celery/app/trace.py", line 450, in trace_task
    R = retval = fun(*args, **kwargs)
  File "/Users/antoniopace/message-in-a-bottle/venv/lib/python3.9/site-packages/celery/app/trace.py", line 731, in __protected_call__
    return self.run(*args, **kwargs)
  File "/Users/antoniopace/message-in-a-bottle/monolith/background.py", line 23, in send_message
    message.receiver= data['receiver']
  File "<string>", line 2, in add
  File "/Users/antoniopace/message-in-a-bottle/venv/lib/python3.9/site-packages/sqlalchemy/orm/scoping.py", line 24, in _proxied
    return self.registry()
  File "/Users/antoniopace/message-in-a-bottle/venv/lib/python3.9/site-packages/sqlalchemy/util/_collections.py", line 1010, in __call__
    return self.registry.setdefault(key, self.createfunc())
  File "/Users/antoniopace/message-in-a-bottle/venv/lib/python3.9/site-packages/sqlalchemy/orm/session.py", line 4172, in __call__
    return self.class_(**local_kw)
  File "/Users/antoniopace/message-in-a-bottle/venv/lib/python3.9/site-packages/flask_sqlalchemy/__init__.py", line 174, in __init__
    self.app = app = db.get_app()
  File "/Users/antoniopace/message-in-a-bottle/venv/lib/python3.9/site-packages/flask_sqlalchemy/__init__.py", line 1042, in get_app
    raise RuntimeError(
RuntimeError: No application found. Either work inside a view function or push an application context. See http://flask-sqlalchemy.pocoo.org/contexts/.
[2021-10-24 17:12:29,067: INFO/MainProcess] Task monolith.background.send_message[3e934459-0ab0-4a78-bccd-d399770af455] received
[2021-10-24 17:12:29,081: WARNING/ForkPoolWorker-6] <Message 82>
[2021-10-24 17:12:29,081: WARNING/ForkPoolWorker-6] 

[2021-10-24 17:12:29,085: INFO/ForkPoolWorker-6] Task monolith.background.send_message[3e934459-0ab0-4a78-bccd-d399770af455] succeeded in 0.016667363999999907s: []
[2021-10-24 17:12:29,764: INFO/MainProcess] Task monolith.background.send_message[f22cd20c-40f7-4ac7-953a-461c97a9675a] received
[2021-10-24 17:12:29,775: WARNING/ForkPoolWorker-6] <Message 83>
[2021-10-24 17:12:29,775: WARNING/ForkPoolWorker-6] 

[2021-10-24 17:12:29,778: INFO/ForkPoolWorker-6] Task monolith.background.send_message[f22cd20c-40f7-4ac7-953a-461c97a9675a] succeeded in 0.012850003000039578s: []
[2021-10-24 17:12:30,474: INFO/MainProcess] Task monolith.background.send_message[df25616d-927c-45e3-a3e9-fd24f02acdcc] received
[2021-10-24 17:12:30,491: WARNING/ForkPoolWorker-6] <Message 84>
[2021-10-24 17:12:30,492: WARNING/ForkPoolWorker-6] 

[2021-10-24 17:12:30,496: INFO/ForkPoolWorker-6] Task monolith.background.send_message[df25616d-927c-45e3-a3e9-fd24f02acdcc] succeeded in 0.02069349099997453s: []
[2021-10-24 17:12:31,180: INFO/MainProcess] Task monolith.background.send_message[995a6696-4d02-45a8-87a0-5a8523a84173] received
[2021-10-24 17:12:31,192: ERROR/ForkPoolWorker-4] Task monolith.background.send_message[995a6696-4d02-45a8-87a0-5a8523a84173] raised unexpected: RuntimeError('No application found. Either work inside a view function or push an application context. See http://flask-sqlalchemy.pocoo.org/contexts/.')
Traceback (most recent call last):
  File "/Users/antoniopace/message-in-a-bottle/venv/lib/python3.9/site-packages/sqlalchemy/util/_collections.py", line 1008, in __call__
    return self.registry[key]
KeyError: <greenlet.greenlet object at 0x7fe78bc0b7d0 (otid=0x7fe78ac4f700) current active started main>

During handling of the above exception, another exception occurred:

Traceback (most recent call last):
  File "/Users/antoniopace/message-in-a-bottle/venv/lib/python3.9/site-packages/celery/app/trace.py", line 450, in trace_task
    R = retval = fun(*args, **kwargs)
  File "/Users/antoniopace/message-in-a-bottle/venv/lib/python3.9/site-packages/celery/app/trace.py", line 731, in __protected_call__
    return self.run(*args, **kwargs)
  File "/Users/antoniopace/message-in-a-bottle/monolith/background.py", line 23, in send_message
    message.receiver= data['receiver']
  File "<string>", line 2, in add
  File "/Users/antoniopace/message-in-a-bottle/venv/lib/python3.9/site-packages/sqlalchemy/orm/scoping.py", line 24, in _proxied
    return self.registry()
  File "/Users/antoniopace/message-in-a-bottle/venv/lib/python3.9/site-packages/sqlalchemy/util/_collections.py", line 1010, in __call__
    return self.registry.setdefault(key, self.createfunc())
  File "/Users/antoniopace/message-in-a-bottle/venv/lib/python3.9/site-packages/sqlalchemy/orm/session.py", line 4172, in __call__
    return self.class_(**local_kw)
  File "/Users/antoniopace/message-in-a-bottle/venv/lib/python3.9/site-packages/flask_sqlalchemy/__init__.py", line 174, in __init__
    self.app = app = db.get_app()
  File "/Users/antoniopace/message-in-a-bottle/venv/lib/python3.9/site-packages/flask_sqlalchemy/__init__.py", line 1042, in get_app
    raise RuntimeError(
RuntimeError: No application found. Either work inside a view function or push an application context. See http://flask-sqlalchemy.pocoo.org/contexts/.
[2021-10-24 17:12:53,339: INFO/MainProcess] Task monolith.background.send_message[f0102c39-7eb7-4078-bf53-55844ceea43b] received
[2021-10-24 17:12:53,351: ERROR/ForkPoolWorker-4] Task monolith.background.send_message[f0102c39-7eb7-4078-bf53-55844ceea43b] raised unexpected: RuntimeError('No application found. Either work inside a view function or push an application context. See http://flask-sqlalchemy.pocoo.org/contexts/.')
Traceback (most recent call last):
  File "/Users/antoniopace/message-in-a-bottle/venv/lib/python3.9/site-packages/sqlalchemy/util/_collections.py", line 1008, in __call__
    return self.registry[key]
KeyError: <greenlet.greenlet object at 0x7fe78bc0b7d0 (otid=0x7fe78ac4f700) current active started main>

During handling of the above exception, another exception occurred:

Traceback (most recent call last):
  File "/Users/antoniopace/message-in-a-bottle/venv/lib/python3.9/site-packages/celery/app/trace.py", line 450, in trace_task
    R = retval = fun(*args, **kwargs)
  File "/Users/antoniopace/message-in-a-bottle/venv/lib/python3.9/site-packages/celery/app/trace.py", line 731, in __protected_call__
    return self.run(*args, **kwargs)
  File "/Users/antoniopace/message-in-a-bottle/monolith/background.py", line 23, in send_message
    message.receiver= data['receiver']
  File "<string>", line 2, in add
  File "/Users/antoniopace/message-in-a-bottle/venv/lib/python3.9/site-packages/sqlalchemy/orm/scoping.py", line 24, in _proxied
    return self.registry()
  File "/Users/antoniopace/message-in-a-bottle/venv/lib/python3.9/site-packages/sqlalchemy/util/_collections.py", line 1010, in __call__
    return self.registry.setdefault(key, self.createfunc())
  File "/Users/antoniopace/message-in-a-bottle/venv/lib/python3.9/site-packages/sqlalchemy/orm/session.py", line 4172, in __call__
    return self.class_(**local_kw)
  File "/Users/antoniopace/message-in-a-bottle/venv/lib/python3.9/site-packages/flask_sqlalchemy/__init__.py", line 174, in __init__
    self.app = app = db.get_app()
  File "/Users/antoniopace/message-in-a-bottle/venv/lib/python3.9/site-packages/flask_sqlalchemy/__init__.py", line 1042, in get_app
    raise RuntimeError(
RuntimeError: No application found. Either work inside a view function or push an application context. See http://flask-sqlalchemy.pocoo.org/contexts/.
[2021-10-24 17:13:17,572: INFO/MainProcess] Task monolith.background.send_message[1774aa1a-49d5-4443-ba71-2a62ef4a2755] received
[2021-10-24 17:13:17,586: WARNING/ForkPoolWorker-6] <Message 85>
[2021-10-24 17:13:17,586: WARNING/ForkPoolWorker-6] 

[2021-10-24 17:13:17,589: INFO/ForkPoolWorker-6] Task monolith.background.send_message[1774aa1a-49d5-4443-ba71-2a62ef4a2755] succeeded in 0.013529743000049166s: []
[2021-10-24 17:13:21,356: INFO/MainProcess] Task monolith.background.send_message[8056dea6-7b92-4816-b4a3-f5d5b4fe79ec] received
[2021-10-24 17:13:21,373: WARNING/ForkPoolWorker-6] <Message 86>
[2021-10-24 17:13:21,374: WARNING/ForkPoolWorker-6] 

[2021-10-24 17:13:21,377: INFO/ForkPoolWorker-6] Task monolith.background.send_message[8056dea6-7b92-4816-b4a3-f5d5b4fe79ec] succeeded in 0.019609295000009297s: []
[2021-10-24 17:13:25,396: INFO/MainProcess] Task monolith.background.send_message[e151962e-0f5d-4c2c-9a21-b8969c8b042a] received
[2021-10-24 17:13:25,412: WARNING/ForkPoolWorker-6] <Message 87>
[2021-10-24 17:13:25,413: WARNING/ForkPoolWorker-6] 

[2021-10-24 17:13:25,416: INFO/ForkPoolWorker-6] Task monolith.background.send_message[e151962e-0f5d-4c2c-9a21-b8969c8b042a] succeeded in 0.013412770999934764s: []
[2021-10-24 17:13:26,886: INFO/MainProcess] Task monolith.background.send_message[0e08acf5-00e8-4f3c-a167-a91682fc3266] received
[2021-10-24 17:13:26,904: ERROR/ForkPoolWorker-4] Task monolith.background.send_message[0e08acf5-00e8-4f3c-a167-a91682fc3266] raised unexpected: RuntimeError('No application found. Either work inside a view function or push an application context. See http://flask-sqlalchemy.pocoo.org/contexts/.')
Traceback (most recent call last):
  File "/Users/antoniopace/message-in-a-bottle/venv/lib/python3.9/site-packages/sqlalchemy/util/_collections.py", line 1008, in __call__
    return self.registry[key]
KeyError: <greenlet.greenlet object at 0x7fe78bc0b7d0 (otid=0x7fe78ac4f700) current active started main>

During handling of the above exception, another exception occurred:

Traceback (most recent call last):
  File "/Users/antoniopace/message-in-a-bottle/venv/lib/python3.9/site-packages/celery/app/trace.py", line 450, in trace_task
    R = retval = fun(*args, **kwargs)
  File "/Users/antoniopace/message-in-a-bottle/venv/lib/python3.9/site-packages/celery/app/trace.py", line 731, in __protected_call__
    return self.run(*args, **kwargs)
  File "/Users/antoniopace/message-in-a-bottle/monolith/background.py", line 23, in send_message
    message.receiver= data['receiver']
  File "<string>", line 2, in add
  File "/Users/antoniopace/message-in-a-bottle/venv/lib/python3.9/site-packages/sqlalchemy/orm/scoping.py", line 24, in _proxied
    return self.registry()
  File "/Users/antoniopace/message-in-a-bottle/venv/lib/python3.9/site-packages/sqlalchemy/util/_collections.py", line 1010, in __call__
    return self.registry.setdefault(key, self.createfunc())
  File "/Users/antoniopace/message-in-a-bottle/venv/lib/python3.9/site-packages/sqlalchemy/orm/session.py", line 4172, in __call__
    return self.class_(**local_kw)
  File "/Users/antoniopace/message-in-a-bottle/venv/lib/python3.9/site-packages/flask_sqlalchemy/__init__.py", line 174, in __init__
    self.app = app = db.get_app()
  File "/Users/antoniopace/message-in-a-bottle/venv/lib/python3.9/site-packages/flask_sqlalchemy/__init__.py", line 1042, in get_app
    raise RuntimeError(
RuntimeError: No application found. Either work inside a view function or push an application context. See http://flask-sqlalchemy.pocoo.org/contexts/.
[2021-10-24 17:13:28,267: INFO/MainProcess] Task monolith.background.send_message[c73c2ba8-fb23-43d3-bce2-093d24cc94ff] received
[2021-10-24 17:13:28,286: WARNING/ForkPoolWorker-6] <Message 88>
[2021-10-24 17:13:28,286: WARNING/ForkPoolWorker-6] 

[2021-10-24 17:13:28,291: INFO/ForkPoolWorker-6] Task monolith.background.send_message[c73c2ba8-fb23-43d3-bce2-093d24cc94ff] succeeded in 0.02314457600004971s: []
[2021-10-24 17:13:28,904: INFO/MainProcess] Task monolith.background.send_message[728b0583-134e-4df1-9b32-198c4f15d979] received
[2021-10-24 17:13:28,921: ERROR/ForkPoolWorker-4] Task monolith.background.send_message[728b0583-134e-4df1-9b32-198c4f15d979] raised unexpected: RuntimeError('No application found. Either work inside a view function or push an application context. See http://flask-sqlalchemy.pocoo.org/contexts/.')
Traceback (most recent call last):
  File "/Users/antoniopace/message-in-a-bottle/venv/lib/python3.9/site-packages/sqlalchemy/util/_collections.py", line 1008, in __call__
    return self.registry[key]
KeyError: <greenlet.greenlet object at 0x7fe78bc0b7d0 (otid=0x7fe78ac4f700) current active started main>

During handling of the above exception, another exception occurred:

Traceback (most recent call last):
  File "/Users/antoniopace/message-in-a-bottle/venv/lib/python3.9/site-packages/celery/app/trace.py", line 450, in trace_task
    R = retval = fun(*args, **kwargs)
  File "/Users/antoniopace/message-in-a-bottle/venv/lib/python3.9/site-packages/celery/app/trace.py", line 731, in __protected_call__
    return self.run(*args, **kwargs)
  File "/Users/antoniopace/message-in-a-bottle/monolith/background.py", line 23, in send_message
    message.receiver= data['receiver']
  File "<string>", line 2, in add
  File "/Users/antoniopace/message-in-a-bottle/venv/lib/python3.9/site-packages/sqlalchemy/orm/scoping.py", line 24, in _proxied
    return self.registry()
  File "/Users/antoniopace/message-in-a-bottle/venv/lib/python3.9/site-packages/sqlalchemy/util/_collections.py", line 1010, in __call__
    return self.registry.setdefault(key, self.createfunc())
  File "/Users/antoniopace/message-in-a-bottle/venv/lib/python3.9/site-packages/sqlalchemy/orm/session.py", line 4172, in __call__
    return self.class_(**local_kw)
  File "/Users/antoniopace/message-in-a-bottle/venv/lib/python3.9/site-packages/flask_sqlalchemy/__init__.py", line 174, in __init__
    self.app = app = db.get_app()
  File "/Users/antoniopace/message-in-a-bottle/venv/lib/python3.9/site-packages/flask_sqlalchemy/__init__.py", line 1042, in get_app
    raise RuntimeError(
RuntimeError: No application found. Either work inside a view function or push an application context. See http://flask-sqlalchemy.pocoo.org/contexts/.
[2021-10-24 17:13:30,876: INFO/MainProcess] Task monolith.background.send_message[c2fe8108-4c16-4799-af8c-1310ae3797dd] received
[2021-10-24 17:13:30,888: ERROR/ForkPoolWorker-4] Task monolith.background.send_message[c2fe8108-4c16-4799-af8c-1310ae3797dd] raised unexpected: RuntimeError('No application found. Either work inside a view function or push an application context. See http://flask-sqlalchemy.pocoo.org/contexts/.')
Traceback (most recent call last):
  File "/Users/antoniopace/message-in-a-bottle/venv/lib/python3.9/site-packages/sqlalchemy/util/_collections.py", line 1008, in __call__
    return self.registry[key]
KeyError: <greenlet.greenlet object at 0x7fe78bc0b7d0 (otid=0x7fe78ac4f700) current active started main>

During handling of the above exception, another exception occurred:

Traceback (most recent call last):
  File "/Users/antoniopace/message-in-a-bottle/venv/lib/python3.9/site-packages/celery/app/trace.py", line 450, in trace_task
    R = retval = fun(*args, **kwargs)
  File "/Users/antoniopace/message-in-a-bottle/venv/lib/python3.9/site-packages/celery/app/trace.py", line 731, in __protected_call__
    return self.run(*args, **kwargs)
  File "/Users/antoniopace/message-in-a-bottle/monolith/background.py", line 23, in send_message
    message.receiver= data['receiver']
  File "<string>", line 2, in add
  File "/Users/antoniopace/message-in-a-bottle/venv/lib/python3.9/site-packages/sqlalchemy/orm/scoping.py", line 24, in _proxied
    return self.registry()
  File "/Users/antoniopace/message-in-a-bottle/venv/lib/python3.9/site-packages/sqlalchemy/util/_collections.py", line 1010, in __call__
    return self.registry.setdefault(key, self.createfunc())
  File "/Users/antoniopace/message-in-a-bottle/venv/lib/python3.9/site-packages/sqlalchemy/orm/session.py", line 4172, in __call__
    return self.class_(**local_kw)
  File "/Users/antoniopace/message-in-a-bottle/venv/lib/python3.9/site-packages/flask_sqlalchemy/__init__.py", line 174, in __init__
    self.app = app = db.get_app()
  File "/Users/antoniopace/message-in-a-bottle/venv/lib/python3.9/site-packages/flask_sqlalchemy/__init__.py", line 1042, in get_app
    raise RuntimeError(
RuntimeError: No application found. Either work inside a view function or push an application context. See http://flask-sqlalchemy.pocoo.org/contexts/.
[2021-10-24 17:13:31,865: INFO/MainProcess] Task monolith.background.send_message[737f47a1-0680-4c1b-b560-7dd0487f7fee] received
[2021-10-24 17:13:31,879: ERROR/ForkPoolWorker-4] Task monolith.background.send_message[737f47a1-0680-4c1b-b560-7dd0487f7fee] raised unexpected: RuntimeError('No application found. Either work inside a view function or push an application context. See http://flask-sqlalchemy.pocoo.org/contexts/.')
Traceback (most recent call last):
  File "/Users/antoniopace/message-in-a-bottle/venv/lib/python3.9/site-packages/sqlalchemy/util/_collections.py", line 1008, in __call__
    return self.registry[key]
KeyError: <greenlet.greenlet object at 0x7fe78bc0b7d0 (otid=0x7fe78ac4f700) current active started main>

During handling of the above exception, another exception occurred:

Traceback (most recent call last):
  File "/Users/antoniopace/message-in-a-bottle/venv/lib/python3.9/site-packages/celery/app/trace.py", line 450, in trace_task
    R = retval = fun(*args, **kwargs)
  File "/Users/antoniopace/message-in-a-bottle/venv/lib/python3.9/site-packages/celery/app/trace.py", line 731, in __protected_call__
    return self.run(*args, **kwargs)
  File "/Users/antoniopace/message-in-a-bottle/monolith/background.py", line 23, in send_message
    message.receiver= data['receiver']
  File "<string>", line 2, in add
  File "/Users/antoniopace/message-in-a-bottle/venv/lib/python3.9/site-packages/sqlalchemy/orm/scoping.py", line 24, in _proxied
    return self.registry()
  File "/Users/antoniopace/message-in-a-bottle/venv/lib/python3.9/site-packages/sqlalchemy/util/_collections.py", line 1010, in __call__
    return self.registry.setdefault(key, self.createfunc())
  File "/Users/antoniopace/message-in-a-bottle/venv/lib/python3.9/site-packages/sqlalchemy/orm/session.py", line 4172, in __call__
    return self.class_(**local_kw)
  File "/Users/antoniopace/message-in-a-bottle/venv/lib/python3.9/site-packages/flask_sqlalchemy/__init__.py", line 174, in __init__
    self.app = app = db.get_app()
  File "/Users/antoniopace/message-in-a-bottle/venv/lib/python3.9/site-packages/flask_sqlalchemy/__init__.py", line 1042, in get_app
    raise RuntimeError(
RuntimeError: No application found. Either work inside a view function or push an application context. See http://flask-sqlalchemy.pocoo.org/contexts/.
[2021-10-24 17:13:33,829: INFO/MainProcess] Task monolith.background.send_message[590b1dc9-47d0-458f-8fa6-adf08839eb32] received
[2021-10-24 17:13:33,844: ERROR/ForkPoolWorker-4] Task monolith.background.send_message[590b1dc9-47d0-458f-8fa6-adf08839eb32] raised unexpected: RuntimeError('No application found. Either work inside a view function or push an application context. See http://flask-sqlalchemy.pocoo.org/contexts/.')
Traceback (most recent call last):
  File "/Users/antoniopace/message-in-a-bottle/venv/lib/python3.9/site-packages/sqlalchemy/util/_collections.py", line 1008, in __call__
    return self.registry[key]
KeyError: <greenlet.greenlet object at 0x7fe78bc0b7d0 (otid=0x7fe78ac4f700) current active started main>

During handling of the above exception, another exception occurred:

Traceback (most recent call last):
  File "/Users/antoniopace/message-in-a-bottle/venv/lib/python3.9/site-packages/celery/app/trace.py", line 450, in trace_task
    R = retval = fun(*args, **kwargs)
  File "/Users/antoniopace/message-in-a-bottle/venv/lib/python3.9/site-packages/celery/app/trace.py", line 731, in __protected_call__
    return self.run(*args, **kwargs)
  File "/Users/antoniopace/message-in-a-bottle/monolith/background.py", line 23, in send_message
    message.receiver= data['receiver']
  File "<string>", line 2, in add
  File "/Users/antoniopace/message-in-a-bottle/venv/lib/python3.9/site-packages/sqlalchemy/orm/scoping.py", line 24, in _proxied
    return self.registry()
  File "/Users/antoniopace/message-in-a-bottle/venv/lib/python3.9/site-packages/sqlalchemy/util/_collections.py", line 1010, in __call__
    return self.registry.setdefault(key, self.createfunc())
  File "/Users/antoniopace/message-in-a-bottle/venv/lib/python3.9/site-packages/sqlalchemy/orm/session.py", line 4172, in __call__
    return self.class_(**local_kw)
  File "/Users/antoniopace/message-in-a-bottle/venv/lib/python3.9/site-packages/flask_sqlalchemy/__init__.py", line 174, in __init__
    self.app = app = db.get_app()
  File "/Users/antoniopace/message-in-a-bottle/venv/lib/python3.9/site-packages/flask_sqlalchemy/__init__.py", line 1042, in get_app
    raise RuntimeError(
RuntimeError: No application found. Either work inside a view function or push an application context. See http://flask-sqlalchemy.pocoo.org/contexts/.
[2021-10-24 17:13:35,091: INFO/MainProcess] Task monolith.background.send_message[0365940e-440d-4f6b-8cdd-d7217a55dad1] received
[2021-10-24 17:13:35,108: WARNING/ForkPoolWorker-6] <Message 89>
[2021-10-24 17:13:35,109: WARNING/ForkPoolWorker-6] 

[2021-10-24 17:13:35,113: INFO/ForkPoolWorker-6] Task monolith.background.send_message[0365940e-440d-4f6b-8cdd-d7217a55dad1] succeeded in 0.02071231499996884s: []
[2021-10-24 17:13:41,925: INFO/MainProcess] Task monolith.background.send_message[b1f9ef94-aa2d-4995-b72e-56d498a75510] received
[2021-10-24 17:13:41,938: ERROR/ForkPoolWorker-4] Task monolith.background.send_message[b1f9ef94-aa2d-4995-b72e-56d498a75510] raised unexpected: RuntimeError('No application found. Either work inside a view function or push an application context. See http://flask-sqlalchemy.pocoo.org/contexts/.')
Traceback (most recent call last):
  File "/Users/antoniopace/message-in-a-bottle/venv/lib/python3.9/site-packages/sqlalchemy/util/_collections.py", line 1008, in __call__
    return self.registry[key]
KeyError: <greenlet.greenlet object at 0x7fe78bc0b7d0 (otid=0x7fe78ac4f700) current active started main>

During handling of the above exception, another exception occurred:

Traceback (most recent call last):
  File "/Users/antoniopace/message-in-a-bottle/venv/lib/python3.9/site-packages/celery/app/trace.py", line 450, in trace_task
    R = retval = fun(*args, **kwargs)
  File "/Users/antoniopace/message-in-a-bottle/venv/lib/python3.9/site-packages/celery/app/trace.py", line 731, in __protected_call__
    return self.run(*args, **kwargs)
  File "/Users/antoniopace/message-in-a-bottle/monolith/background.py", line 23, in send_message
    message.receiver= data['receiver']
  File "<string>", line 2, in add
  File "/Users/antoniopace/message-in-a-bottle/venv/lib/python3.9/site-packages/sqlalchemy/orm/scoping.py", line 24, in _proxied
    return self.registry()
  File "/Users/antoniopace/message-in-a-bottle/venv/lib/python3.9/site-packages/sqlalchemy/util/_collections.py", line 1010, in __call__
    return self.registry.setdefault(key, self.createfunc())
  File "/Users/antoniopace/message-in-a-bottle/venv/lib/python3.9/site-packages/sqlalchemy/orm/session.py", line 4172, in __call__
    return self.class_(**local_kw)
  File "/Users/antoniopace/message-in-a-bottle/venv/lib/python3.9/site-packages/flask_sqlalchemy/__init__.py", line 174, in __init__
    self.app = app = db.get_app()
  File "/Users/antoniopace/message-in-a-bottle/venv/lib/python3.9/site-packages/flask_sqlalchemy/__init__.py", line 1042, in get_app
    raise RuntimeError(
RuntimeError: No application found. Either work inside a view function or push an application context. See http://flask-sqlalchemy.pocoo.org/contexts/.
[2021-10-24 17:13:43,146: INFO/MainProcess] Task monolith.background.send_message[c1454491-adb6-478a-82ef-4cfd8cea622e] received
[2021-10-24 17:13:43,164: WARNING/ForkPoolWorker-6] <Message 90>
[2021-10-24 17:13:43,164: WARNING/ForkPoolWorker-6] 

[2021-10-24 17:13:43,168: INFO/ForkPoolWorker-6] Task monolith.background.send_message[c1454491-adb6-478a-82ef-4cfd8cea622e] succeeded in 0.02185410199990656s: []
[2021-10-24 17:13:43,893: INFO/MainProcess] Task monolith.background.send_message[8b7764ca-6ff6-4027-8982-af3ada1d2203] received
[2021-10-24 17:13:43,906: ERROR/ForkPoolWorker-4] Task monolith.background.send_message[8b7764ca-6ff6-4027-8982-af3ada1d2203] raised unexpected: RuntimeError('No application found. Either work inside a view function or push an application context. See http://flask-sqlalchemy.pocoo.org/contexts/.')
Traceback (most recent call last):
  File "/Users/antoniopace/message-in-a-bottle/venv/lib/python3.9/site-packages/sqlalchemy/util/_collections.py", line 1008, in __call__
    return self.registry[key]
KeyError: <greenlet.greenlet object at 0x7fe78bc0b7d0 (otid=0x7fe78ac4f700) current active started main>

During handling of the above exception, another exception occurred:

Traceback (most recent call last):
  File "/Users/antoniopace/message-in-a-bottle/venv/lib/python3.9/site-packages/celery/app/trace.py", line 450, in trace_task
    R = retval = fun(*args, **kwargs)
  File "/Users/antoniopace/message-in-a-bottle/venv/lib/python3.9/site-packages/celery/app/trace.py", line 731, in __protected_call__
    return self.run(*args, **kwargs)
  File "/Users/antoniopace/message-in-a-bottle/monolith/background.py", line 23, in send_message
    message.receiver= data['receiver']
  File "<string>", line 2, in add
  File "/Users/antoniopace/message-in-a-bottle/venv/lib/python3.9/site-packages/sqlalchemy/orm/scoping.py", line 24, in _proxied
    return self.registry()
  File "/Users/antoniopace/message-in-a-bottle/venv/lib/python3.9/site-packages/sqlalchemy/util/_collections.py", line 1010, in __call__
    return self.registry.setdefault(key, self.createfunc())
  File "/Users/antoniopace/message-in-a-bottle/venv/lib/python3.9/site-packages/sqlalchemy/orm/session.py", line 4172, in __call__
    return self.class_(**local_kw)
  File "/Users/antoniopace/message-in-a-bottle/venv/lib/python3.9/site-packages/flask_sqlalchemy/__init__.py", line 174, in __init__
    self.app = app = db.get_app()
  File "/Users/antoniopace/message-in-a-bottle/venv/lib/python3.9/site-packages/flask_sqlalchemy/__init__.py", line 1042, in get_app
    raise RuntimeError(
RuntimeError: No application found. Either work inside a view function or push an application context. See http://flask-sqlalchemy.pocoo.org/contexts/.
[2021-10-24 17:13:44,964: INFO/MainProcess] Task monolith.background.send_message[7f67f1e5-53dd-46d0-8d3e-9faa9fe45f5e] received
[2021-10-24 17:13:44,982: WARNING/ForkPoolWorker-6] <Message 91>
[2021-10-24 17:13:44,982: WARNING/ForkPoolWorker-6] 

[2021-10-24 17:13:44,986: INFO/ForkPoolWorker-6] Task monolith.background.send_message[7f67f1e5-53dd-46d0-8d3e-9faa9fe45f5e] succeeded in 0.021542195000051834s: []
[2021-10-24 17:13:45,818: INFO/MainProcess] Task monolith.background.send_message[df354f1a-6392-4584-ae32-8627e41baff4] received
[2021-10-24 17:13:45,831: ERROR/ForkPoolWorker-4] Task monolith.background.send_message[df354f1a-6392-4584-ae32-8627e41baff4] raised unexpected: RuntimeError('No application found. Either work inside a view function or push an application context. See http://flask-sqlalchemy.pocoo.org/contexts/.')
Traceback (most recent call last):
  File "/Users/antoniopace/message-in-a-bottle/venv/lib/python3.9/site-packages/sqlalchemy/util/_collections.py", line 1008, in __call__
    return self.registry[key]
KeyError: <greenlet.greenlet object at 0x7fe78bc0b7d0 (otid=0x7fe78ac4f700) current active started main>

During handling of the above exception, another exception occurred:

Traceback (most recent call last):
  File "/Users/antoniopace/message-in-a-bottle/venv/lib/python3.9/site-packages/celery/app/trace.py", line 450, in trace_task
    R = retval = fun(*args, **kwargs)
  File "/Users/antoniopace/message-in-a-bottle/venv/lib/python3.9/site-packages/celery/app/trace.py", line 731, in __protected_call__
    return self.run(*args, **kwargs)
  File "/Users/antoniopace/message-in-a-bottle/monolith/background.py", line 23, in send_message
    message.receiver= data['receiver']
  File "<string>", line 2, in add
  File "/Users/antoniopace/message-in-a-bottle/venv/lib/python3.9/site-packages/sqlalchemy/orm/scoping.py", line 24, in _proxied
    return self.registry()
  File "/Users/antoniopace/message-in-a-bottle/venv/lib/python3.9/site-packages/sqlalchemy/util/_collections.py", line 1010, in __call__
    return self.registry.setdefault(key, self.createfunc())
  File "/Users/antoniopace/message-in-a-bottle/venv/lib/python3.9/site-packages/sqlalchemy/orm/session.py", line 4172, in __call__
    return self.class_(**local_kw)
  File "/Users/antoniopace/message-in-a-bottle/venv/lib/python3.9/site-packages/flask_sqlalchemy/__init__.py", line 174, in __init__
    self.app = app = db.get_app()
  File "/Users/antoniopace/message-in-a-bottle/venv/lib/python3.9/site-packages/flask_sqlalchemy/__init__.py", line 1042, in get_app
    raise RuntimeError(
RuntimeError: No application found. Either work inside a view function or push an application context. See http://flask-sqlalchemy.pocoo.org/contexts/.
[2021-10-24 17:13:47,644: INFO/MainProcess] Task monolith.background.send_message[13b4cf5c-cd99-43b6-9055-cfa34371c1fd] received
[2021-10-24 17:13:47,656: ERROR/ForkPoolWorker-4] Task monolith.background.send_message[13b4cf5c-cd99-43b6-9055-cfa34371c1fd] raised unexpected: RuntimeError('No application found. Either work inside a view function or push an application context. See http://flask-sqlalchemy.pocoo.org/contexts/.')
Traceback (most recent call last):
  File "/Users/antoniopace/message-in-a-bottle/venv/lib/python3.9/site-packages/sqlalchemy/util/_collections.py", line 1008, in __call__
    return self.registry[key]
KeyError: <greenlet.greenlet object at 0x7fe78bc0b7d0 (otid=0x7fe78ac4f700) current active started main>

During handling of the above exception, another exception occurred:

Traceback (most recent call last):
  File "/Users/antoniopace/message-in-a-bottle/venv/lib/python3.9/site-packages/celery/app/trace.py", line 450, in trace_task
    R = retval = fun(*args, **kwargs)
  File "/Users/antoniopace/message-in-a-bottle/venv/lib/python3.9/site-packages/celery/app/trace.py", line 731, in __protected_call__
    return self.run(*args, **kwargs)
  File "/Users/antoniopace/message-in-a-bottle/monolith/background.py", line 23, in send_message
    message.receiver= data['receiver']
  File "<string>", line 2, in add
  File "/Users/antoniopace/message-in-a-bottle/venv/lib/python3.9/site-packages/sqlalchemy/orm/scoping.py", line 24, in _proxied
    return self.registry()
  File "/Users/antoniopace/message-in-a-bottle/venv/lib/python3.9/site-packages/sqlalchemy/util/_collections.py", line 1010, in __call__
    return self.registry.setdefault(key, self.createfunc())
  File "/Users/antoniopace/message-in-a-bottle/venv/lib/python3.9/site-packages/sqlalchemy/orm/session.py", line 4172, in __call__
    return self.class_(**local_kw)
  File "/Users/antoniopace/message-in-a-bottle/venv/lib/python3.9/site-packages/flask_sqlalchemy/__init__.py", line 174, in __init__
    self.app = app = db.get_app()
  File "/Users/antoniopace/message-in-a-bottle/venv/lib/python3.9/site-packages/flask_sqlalchemy/__init__.py", line 1042, in get_app
    raise RuntimeError(
RuntimeError: No application found. Either work inside a view function or push an application context. See http://flask-sqlalchemy.pocoo.org/contexts/.
[2021-10-24 17:13:48,763: INFO/MainProcess] Task monolith.background.send_message[7ae0f4f5-c12d-408a-b09a-45bf8d4d88e3] received
[2021-10-24 17:13:48,782: WARNING/ForkPoolWorker-6] <Message 92>
[2021-10-24 17:13:48,782: WARNING/ForkPoolWorker-6] 

[2021-10-24 17:13:48,787: INFO/ForkPoolWorker-6] Task monolith.background.send_message[7ae0f4f5-c12d-408a-b09a-45bf8d4d88e3] succeeded in 0.02251873800003068s: []
[2021-10-24 17:15:11,634: INFO/MainProcess] Task monolith.background.send_message[0592c433-0953-4bdc-847e-0369cb4962e7] received
[2021-10-24 17:15:11,646: ERROR/ForkPoolWorker-4] Task monolith.background.send_message[0592c433-0953-4bdc-847e-0369cb4962e7] raised unexpected: RuntimeError('No application found. Either work inside a view function or push an application context. See http://flask-sqlalchemy.pocoo.org/contexts/.')
Traceback (most recent call last):
  File "/Users/antoniopace/message-in-a-bottle/venv/lib/python3.9/site-packages/sqlalchemy/util/_collections.py", line 1008, in __call__
    return self.registry[key]
KeyError: <greenlet.greenlet object at 0x7fe78bc0b7d0 (otid=0x7fe78ac4f700) current active started main>

During handling of the above exception, another exception occurred:

Traceback (most recent call last):
  File "/Users/antoniopace/message-in-a-bottle/venv/lib/python3.9/site-packages/celery/app/trace.py", line 450, in trace_task
    R = retval = fun(*args, **kwargs)
  File "/Users/antoniopace/message-in-a-bottle/venv/lib/python3.9/site-packages/celery/app/trace.py", line 731, in __protected_call__
    return self.run(*args, **kwargs)
  File "/Users/antoniopace/message-in-a-bottle/monolith/background.py", line 23, in send_message
    message.receiver= data['receiver']
  File "<string>", line 2, in add
  File "/Users/antoniopace/message-in-a-bottle/venv/lib/python3.9/site-packages/sqlalchemy/orm/scoping.py", line 24, in _proxied
    return self.registry()
  File "/Users/antoniopace/message-in-a-bottle/venv/lib/python3.9/site-packages/sqlalchemy/util/_collections.py", line 1010, in __call__
    return self.registry.setdefault(key, self.createfunc())
  File "/Users/antoniopace/message-in-a-bottle/venv/lib/python3.9/site-packages/sqlalchemy/orm/session.py", line 4172, in __call__
    return self.class_(**local_kw)
  File "/Users/antoniopace/message-in-a-bottle/venv/lib/python3.9/site-packages/flask_sqlalchemy/__init__.py", line 174, in __init__
    self.app = app = db.get_app()
  File "/Users/antoniopace/message-in-a-bottle/venv/lib/python3.9/site-packages/flask_sqlalchemy/__init__.py", line 1042, in get_app
    raise RuntimeError(
RuntimeError: No application found. Either work inside a view function or push an application context. See http://flask-sqlalchemy.pocoo.org/contexts/.
[2021-10-24 17:15:48,679: INFO/MainProcess] Task monolith.background.send_message[ce8fd749-c20b-48ff-a8de-e3c29b61f49b] received
[2021-10-24 17:15:48,693: ERROR/ForkPoolWorker-4] Task monolith.background.send_message[ce8fd749-c20b-48ff-a8de-e3c29b61f49b] raised unexpected: RuntimeError('No application found. Either work inside a view function or push an application context. See http://flask-sqlalchemy.pocoo.org/contexts/.')
Traceback (most recent call last):
  File "/Users/antoniopace/message-in-a-bottle/venv/lib/python3.9/site-packages/sqlalchemy/util/_collections.py", line 1008, in __call__
    return self.registry[key]
KeyError: <greenlet.greenlet object at 0x7fe78bc0b7d0 (otid=0x7fe78ac4f700) current active started main>

During handling of the above exception, another exception occurred:

Traceback (most recent call last):
  File "/Users/antoniopace/message-in-a-bottle/venv/lib/python3.9/site-packages/celery/app/trace.py", line 450, in trace_task
    R = retval = fun(*args, **kwargs)
  File "/Users/antoniopace/message-in-a-bottle/venv/lib/python3.9/site-packages/celery/app/trace.py", line 731, in __protected_call__
    return self.run(*args, **kwargs)
  File "/Users/antoniopace/message-in-a-bottle/monolith/background.py", line 23, in send_message
    message.receiver= data['receiver']
  File "<string>", line 2, in add
  File "/Users/antoniopace/message-in-a-bottle/venv/lib/python3.9/site-packages/sqlalchemy/orm/scoping.py", line 24, in _proxied
    return self.registry()
  File "/Users/antoniopace/message-in-a-bottle/venv/lib/python3.9/site-packages/sqlalchemy/util/_collections.py", line 1010, in __call__
    return self.registry.setdefault(key, self.createfunc())
  File "/Users/antoniopace/message-in-a-bottle/venv/lib/python3.9/site-packages/sqlalchemy/orm/session.py", line 4172, in __call__
    return self.class_(**local_kw)
  File "/Users/antoniopace/message-in-a-bottle/venv/lib/python3.9/site-packages/flask_sqlalchemy/__init__.py", line 174, in __init__
    self.app = app = db.get_app()
  File "/Users/antoniopace/message-in-a-bottle/venv/lib/python3.9/site-packages/flask_sqlalchemy/__init__.py", line 1042, in get_app
    raise RuntimeError(
RuntimeError: No application found. Either work inside a view function or push an application context. See http://flask-sqlalchemy.pocoo.org/contexts/.
[2021-10-24 17:15:58,407: INFO/MainProcess] Task monolith.background.send_message[f5668d36-19b5-4e72-9990-b395c310ee9b] received
[2021-10-24 17:15:58,421: WARNING/ForkPoolWorker-6] <Message 93>
[2021-10-24 17:15:58,421: WARNING/ForkPoolWorker-6] 

[2021-10-24 17:15:58,424: INFO/ForkPoolWorker-6] Task monolith.background.send_message[f5668d36-19b5-4e72-9990-b395c310ee9b] succeeded in 0.015445070000055239s: []
[2021-10-24 17:16:00,311: INFO/MainProcess] Task monolith.background.send_message[21463e6d-fd5f-40af-802f-87c1bbf392af] received
[2021-10-24 17:16:00,326: WARNING/ForkPoolWorker-6] <Message 94>
[2021-10-24 17:16:00,327: WARNING/ForkPoolWorker-6] 

[2021-10-24 17:16:00,331: INFO/ForkPoolWorker-6] Task monolith.background.send_message[21463e6d-fd5f-40af-802f-87c1bbf392af] succeeded in 0.018794395999975677s: []
[2021-10-24 17:16:01,780: INFO/MainProcess] Task monolith.background.send_message[ad5202e5-00f5-4b44-b1e9-7fec9d2aa498] received
[2021-10-24 17:16:01,794: ERROR/ForkPoolWorker-4] Task monolith.background.send_message[ad5202e5-00f5-4b44-b1e9-7fec9d2aa498] raised unexpected: RuntimeError('No application found. Either work inside a view function or push an application context. See http://flask-sqlalchemy.pocoo.org/contexts/.')
Traceback (most recent call last):
  File "/Users/antoniopace/message-in-a-bottle/venv/lib/python3.9/site-packages/sqlalchemy/util/_collections.py", line 1008, in __call__
    return self.registry[key]
KeyError: <greenlet.greenlet object at 0x7fe78bc0b7d0 (otid=0x7fe78ac4f700) current active started main>

During handling of the above exception, another exception occurred:

Traceback (most recent call last):
  File "/Users/antoniopace/message-in-a-bottle/venv/lib/python3.9/site-packages/celery/app/trace.py", line 450, in trace_task
    R = retval = fun(*args, **kwargs)
  File "/Users/antoniopace/message-in-a-bottle/venv/lib/python3.9/site-packages/celery/app/trace.py", line 731, in __protected_call__
    return self.run(*args, **kwargs)
  File "/Users/antoniopace/message-in-a-bottle/monolith/background.py", line 23, in send_message
    message.receiver= data['receiver']
  File "<string>", line 2, in add
  File "/Users/antoniopace/message-in-a-bottle/venv/lib/python3.9/site-packages/sqlalchemy/orm/scoping.py", line 24, in _proxied
    return self.registry()
  File "/Users/antoniopace/message-in-a-bottle/venv/lib/python3.9/site-packages/sqlalchemy/util/_collections.py", line 1010, in __call__
    return self.registry.setdefault(key, self.createfunc())
  File "/Users/antoniopace/message-in-a-bottle/venv/lib/python3.9/site-packages/sqlalchemy/orm/session.py", line 4172, in __call__
    return self.class_(**local_kw)
  File "/Users/antoniopace/message-in-a-bottle/venv/lib/python3.9/site-packages/flask_sqlalchemy/__init__.py", line 174, in __init__
    self.app = app = db.get_app()
  File "/Users/antoniopace/message-in-a-bottle/venv/lib/python3.9/site-packages/flask_sqlalchemy/__init__.py", line 1042, in get_app
    raise RuntimeError(
RuntimeError: No application found. Either work inside a view function or push an application context. See http://flask-sqlalchemy.pocoo.org/contexts/.
[2021-10-24 17:16:03,336: INFO/MainProcess] Task monolith.background.send_message[6c544f11-5e8b-4844-aefc-1ce6ea206849] received
[2021-10-24 17:16:03,348: WARNING/ForkPoolWorker-6] <Message 95>
[2021-10-24 17:16:03,348: WARNING/ForkPoolWorker-6] 

[2021-10-24 17:16:03,351: INFO/ForkPoolWorker-6] Task monolith.background.send_message[6c544f11-5e8b-4844-aefc-1ce6ea206849] succeeded in 0.014023034000047119s: []
 
 -------------- celery@MBPro.local v5.1.2 (sun-harmonics)
--- ***** ----- 
-- ******* ---- macOS-11.5.2-x86_64-i386-64bit 2021-10-24 17:46:42
- *** --- * --- 
- ** ---------- [config]
- ** ---------- .> app:         monolith.background:0x110a2a190
- ** ---------- .> transport:   redis://localhost:6379//
- ** ---------- .> results:     redis://localhost:6379/
- *** --- * --- .> concurrency: 4 (prefork)
-- ******* ---- .> task events: OFF (enable -E to monitor tasks in this worker)
--- ***** ----- 
 -------------- [queues]
                .> celery           exchange=celery(direct) key=celery
                

[tasks]
  . monolith.background.send_message

[2021-10-24 17:46:42,515: INFO/MainProcess] Connected to redis://localhost:6379//
[2021-10-24 17:46:42,527: INFO/MainProcess] mingle: searching for neighbors
[2021-10-24 17:46:43,594: WARNING/MainProcess] /usr/local/lib/python3.9/site-packages/celery/app/control.py:56: DuplicateNodenameWarning: Received multiple replies from node name: celery@MBPro.local.
Please make sure you give each node a unique nodename using
the celery worker `-n` option.
  warnings.warn(DuplicateNodenameWarning(

[2021-10-24 17:46:43,595: INFO/MainProcess] mingle: all alone
[2021-10-24 17:46:43,630: INFO/MainProcess] celery@MBPro.local ready.

worker: Hitting Ctrl+C again will terminate all running tasks!

worker: Warm shutdown (MainProcess)
 
 -------------- celery@MBPro.local v5.1.2 (sun-harmonics)
--- ***** ----- 
-- ******* ---- macOS-11.5.2-x86_64-i386-64bit 2021-10-24 17:49:51
- *** --- * --- 
- ** ---------- [config]
- ** ---------- .> app:         monolith.background:0x1076fb190
- ** ---------- .> transport:   redis://localhost:6379//
- ** ---------- .> results:     redis://localhost:6379/
- *** --- * --- .> concurrency: 4 (prefork)
-- ******* ---- .> task events: OFF (enable -E to monitor tasks in this worker)
--- ***** ----- 
 -------------- [queues]
                .> celery           exchange=celery(direct) key=celery
                

[tasks]
  . monolith.background.send_message

[2021-10-24 17:49:51,703: INFO/MainProcess] Connected to redis://localhost:6379//
[2021-10-24 17:49:51,717: INFO/MainProcess] mingle: searching for neighbors
[2021-10-24 17:49:52,753: WARNING/MainProcess] /usr/local/lib/python3.9/site-packages/celery/app/control.py:56: DuplicateNodenameWarning: Received multiple replies from node name: celery@MBPro.local.
Please make sure you give each node a unique nodename using
the celery worker `-n` option.
  warnings.warn(DuplicateNodenameWarning(

[2021-10-24 17:49:52,754: INFO/MainProcess] mingle: all alone
[2021-10-24 17:49:52,778: INFO/MainProcess] celery@MBPro.local ready.
[2021-10-24 17:51:39,698: INFO/MainProcess] Task monolith.background.send_message[08bc0a0b-a226-4396-94a4-eabbb14a799f] received
[2021-10-24 17:51:39,761: WARNING/ForkPoolWorker-6] <Message 96>
[2021-10-24 17:51:39,762: WARNING/ForkPoolWorker-6] 

[2021-10-24 17:51:39,767: INFO/ForkPoolWorker-6] Task monolith.background.send_message[08bc0a0b-a226-4396-94a4-eabbb14a799f] succeeded in 0.06356323799991515s: []
[2021-10-24 17:51:46,267: INFO/MainProcess] Task monolith.background.send_message[5db3f377-770c-416d-adab-0f5fed4615f4] received
[2021-10-24 17:51:46,295: WARNING/ForkPoolWorker-2] <Message 97>
[2021-10-24 17:51:46,297: WARNING/ForkPoolWorker-2] 

[2021-10-24 17:51:46,314: INFO/ForkPoolWorker-2] Task monolith.background.send_message[5db3f377-770c-416d-adab-0f5fed4615f4] succeeded in 0.04343346799998926s: []
[2021-10-24 17:51:48,236: INFO/MainProcess] Task monolith.background.send_message[7d6bd141-5c8c-4f2e-8086-19ced6e03a79] received
[2021-10-24 17:51:48,268: WARNING/ForkPoolWorker-2] <Message 98>
[2021-10-24 17:51:48,269: WARNING/ForkPoolWorker-2] 

[2021-10-24 17:51:48,273: INFO/ForkPoolWorker-2] Task monolith.background.send_message[7d6bd141-5c8c-4f2e-8086-19ced6e03a79] succeeded in 0.03645223399999509s: []
[2021-10-24 17:51:49,074: INFO/MainProcess] Task monolith.background.send_message[f3edbfdc-b142-4324-a30c-29eb2604aa40] received
[2021-10-24 17:51:49,094: WARNING/ForkPoolWorker-2] <Message 99>
[2021-10-24 17:51:49,095: WARNING/ForkPoolWorker-2] 

[2021-10-24 17:51:49,098: INFO/ForkPoolWorker-2] Task monolith.background.send_message[f3edbfdc-b142-4324-a30c-29eb2604aa40] succeeded in 0.020194180999993705s: []
[2021-10-24 17:51:49,897: INFO/MainProcess] Task monolith.background.send_message[94d0faff-9af0-4c4e-b1ad-5dc0f6764f62] received
[2021-10-24 17:51:49,912: WARNING/ForkPoolWorker-6] <Message 100>
[2021-10-24 17:51:49,913: WARNING/ForkPoolWorker-6] 

[2021-10-24 17:51:49,916: INFO/ForkPoolWorker-6] Task monolith.background.send_message[94d0faff-9af0-4c4e-b1ad-5dc0f6764f62] succeeded in 0.018023498999809817s: []
[2021-10-24 17:51:50,738: INFO/MainProcess] Task monolith.background.send_message[9457524a-0304-478c-8629-99645f1b9c95] received
[2021-10-24 17:51:50,750: WARNING/ForkPoolWorker-6] <Message 101>
[2021-10-24 17:51:50,750: WARNING/ForkPoolWorker-6] 

[2021-10-24 17:51:50,753: INFO/ForkPoolWorker-6] Task monolith.background.send_message[9457524a-0304-478c-8629-99645f1b9c95] succeeded in 0.013768685999821173s: []
[2021-10-24 17:51:51,590: INFO/MainProcess] Task monolith.background.send_message[e7f593bf-7d3e-4587-b49d-de27d1bfbb66] received
[2021-10-24 17:51:51,646: WARNING/ForkPoolWorker-6] <Message 102>
[2021-10-24 17:51:51,647: WARNING/ForkPoolWorker-6] 

[2021-10-24 17:51:51,650: INFO/ForkPoolWorker-6] Task monolith.background.send_message[e7f593bf-7d3e-4587-b49d-de27d1bfbb66] succeeded in 0.058643840000058844s: []
[2021-10-24 17:51:52,564: INFO/MainProcess] Task monolith.background.send_message[9621b2b0-4d30-468f-9eb6-3f4c29562239] received
[2021-10-24 17:51:52,587: WARNING/ForkPoolWorker-6] <Message 103>
[2021-10-24 17:51:52,587: WARNING/ForkPoolWorker-6] 

[2021-10-24 17:51:52,592: INFO/ForkPoolWorker-6] Task monolith.background.send_message[9621b2b0-4d30-468f-9eb6-3f4c29562239] succeeded in 0.027447455000128684s: []
[2021-10-24 17:51:53,386: INFO/MainProcess] Task monolith.background.send_message[ba74ed20-b900-4155-b3e0-499af2bf74f9] received
[2021-10-24 17:51:53,467: ERROR/ForkPoolWorker-4] Task monolith.background.send_message[ba74ed20-b900-4155-b3e0-499af2bf74f9] raised unexpected: RuntimeError('No application found. Either work inside a view function or push an application context. See http://flask-sqlalchemy.pocoo.org/contexts/.')
Traceback (most recent call last):
  File "/Users/antoniopace/message-in-a-bottle/venv/lib/python3.9/site-packages/sqlalchemy/util/_collections.py", line 1008, in __call__
    return self.registry[key]
KeyError: <greenlet.greenlet object at 0x7fe78bc0b7d0 (otid=0x7fe78ac4f700) current active started main>

During handling of the above exception, another exception occurred:

Traceback (most recent call last):
  File "/Users/antoniopace/message-in-a-bottle/venv/lib/python3.9/site-packages/celery/app/trace.py", line 450, in trace_task
    R = retval = fun(*args, **kwargs)
  File "/Users/antoniopace/message-in-a-bottle/venv/lib/python3.9/site-packages/celery/app/trace.py", line 731, in __protected_call__
    return self.run(*args, **kwargs)
  File "/Users/antoniopace/message-in-a-bottle/monolith/background.py", line 23, in send_message
    message.sender= data['sender']
  File "<string>", line 2, in add
  File "/Users/antoniopace/message-in-a-bottle/venv/lib/python3.9/site-packages/sqlalchemy/orm/scoping.py", line 24, in _proxied
    return self.registry()
  File "/Users/antoniopace/message-in-a-bottle/venv/lib/python3.9/site-packages/sqlalchemy/util/_collections.py", line 1010, in __call__
    return self.registry.setdefault(key, self.createfunc())
  File "/Users/antoniopace/message-in-a-bottle/venv/lib/python3.9/site-packages/sqlalchemy/orm/session.py", line 4172, in __call__
    return self.class_(**local_kw)
  File "/Users/antoniopace/message-in-a-bottle/venv/lib/python3.9/site-packages/flask_sqlalchemy/__init__.py", line 174, in __init__
    self.app = app = db.get_app()
  File "/Users/antoniopace/message-in-a-bottle/venv/lib/python3.9/site-packages/flask_sqlalchemy/__init__.py", line 1042, in get_app
    raise RuntimeError(
RuntimeError: No application found. Either work inside a view function or push an application context. See http://flask-sqlalchemy.pocoo.org/contexts/.
[2021-10-24 17:51:57,590: INFO/MainProcess] Task monolith.background.send_message[09efb56a-89e9-43bc-9f01-e45d4aa3cc8f] received
[2021-10-24 17:51:57,604: WARNING/ForkPoolWorker-6] <Message 104>
[2021-10-24 17:51:57,604: WARNING/ForkPoolWorker-6] 

[2021-10-24 17:51:57,607: INFO/ForkPoolWorker-6] Task monolith.background.send_message[09efb56a-89e9-43bc-9f01-e45d4aa3cc8f] succeeded in 0.013447874999656051s: []
[2021-10-24 17:51:58,525: INFO/MainProcess] Task monolith.background.send_message[d0d8717e-0df0-4552-9d72-3a88121200f3] received
[2021-10-24 17:51:58,544: WARNING/ForkPoolWorker-6] <Message 105>
[2021-10-24 17:51:58,545: WARNING/ForkPoolWorker-6] 

[2021-10-24 17:51:58,549: INFO/ForkPoolWorker-6] Task monolith.background.send_message[d0d8717e-0df0-4552-9d72-3a88121200f3] succeeded in 0.020177378999960638s: []
[2021-10-24 17:51:59,400: INFO/MainProcess] Task monolith.background.send_message[28f202a7-414f-4ecb-9864-4d0c9dadf446] received
[2021-10-24 17:51:59,411: ERROR/ForkPoolWorker-4] Task monolith.background.send_message[28f202a7-414f-4ecb-9864-4d0c9dadf446] raised unexpected: RuntimeError('No application found. Either work inside a view function or push an application context. See http://flask-sqlalchemy.pocoo.org/contexts/.')
Traceback (most recent call last):
  File "/Users/antoniopace/message-in-a-bottle/venv/lib/python3.9/site-packages/sqlalchemy/util/_collections.py", line 1008, in __call__
    return self.registry[key]
KeyError: <greenlet.greenlet object at 0x7fe78bc0b7d0 (otid=0x7fe78ac4f700) current active started main>

During handling of the above exception, another exception occurred:

Traceback (most recent call last):
  File "/Users/antoniopace/message-in-a-bottle/venv/lib/python3.9/site-packages/celery/app/trace.py", line 450, in trace_task
    R = retval = fun(*args, **kwargs)
  File "/Users/antoniopace/message-in-a-bottle/venv/lib/python3.9/site-packages/celery/app/trace.py", line 731, in __protected_call__
    return self.run(*args, **kwargs)
  File "/Users/antoniopace/message-in-a-bottle/monolith/background.py", line 23, in send_message
    message.sender= data['sender']
  File "<string>", line 2, in add
  File "/Users/antoniopace/message-in-a-bottle/venv/lib/python3.9/site-packages/sqlalchemy/orm/scoping.py", line 24, in _proxied
    return self.registry()
  File "/Users/antoniopace/message-in-a-bottle/venv/lib/python3.9/site-packages/sqlalchemy/util/_collections.py", line 1010, in __call__
    return self.registry.setdefault(key, self.createfunc())
  File "/Users/antoniopace/message-in-a-bottle/venv/lib/python3.9/site-packages/sqlalchemy/orm/session.py", line 4172, in __call__
    return self.class_(**local_kw)
  File "/Users/antoniopace/message-in-a-bottle/venv/lib/python3.9/site-packages/flask_sqlalchemy/__init__.py", line 174, in __init__
    self.app = app = db.get_app()
  File "/Users/antoniopace/message-in-a-bottle/venv/lib/python3.9/site-packages/flask_sqlalchemy/__init__.py", line 1042, in get_app
    raise RuntimeError(
RuntimeError: No application found. Either work inside a view function or push an application context. See http://flask-sqlalchemy.pocoo.org/contexts/.
[2021-10-24 17:52:00,319: INFO/MainProcess] Task monolith.background.send_message[8b889bf5-07bf-49f2-bddb-834200285e6a] received
[2021-10-24 17:52:00,339: WARNING/ForkPoolWorker-2] <Message 106>
[2021-10-24 17:52:00,340: WARNING/ForkPoolWorker-2] 

[2021-10-24 17:52:00,347: INFO/ForkPoolWorker-2] Task monolith.background.send_message[8b889bf5-07bf-49f2-bddb-834200285e6a] succeeded in 0.027187128999997867s: []
[2021-10-24 17:52:03,387: INFO/MainProcess] Task monolith.background.send_message[5cae1242-09f8-4a0c-af61-79d22e09c752] received
[2021-10-24 17:52:03,399: WARNING/ForkPoolWorker-2] <Message 107>
[2021-10-24 17:52:03,399: WARNING/ForkPoolWorker-2] 

[2021-10-24 17:52:03,402: INFO/ForkPoolWorker-2] Task monolith.background.send_message[5cae1242-09f8-4a0c-af61-79d22e09c752] succeeded in 0.014069903999995859s: []
[2021-10-24 17:52:05,420: INFO/MainProcess] Task monolith.background.send_message[1ce29908-b3d3-4115-ad2c-d494cfd2eb57] received
[2021-10-24 17:52:05,432: WARNING/ForkPoolWorker-2] <Message 108>
[2021-10-24 17:52:05,433: WARNING/ForkPoolWorker-2] 

[2021-10-24 17:52:05,436: INFO/ForkPoolWorker-2] Task monolith.background.send_message[1ce29908-b3d3-4115-ad2c-d494cfd2eb57] succeeded in 0.015032898999976396s: []
[2021-10-24 17:52:08,412: INFO/MainProcess] Task monolith.background.send_message[5b5b62e9-0a02-4523-bec1-960a0200a514] received
[2021-10-24 17:52:08,425: WARNING/ForkPoolWorker-2] <Message 109>
[2021-10-24 17:52:08,425: WARNING/ForkPoolWorker-2] 

[2021-10-24 17:52:08,428: INFO/ForkPoolWorker-2] Task monolith.background.send_message[5b5b62e9-0a02-4523-bec1-960a0200a514] succeeded in 0.014765748000002077s: []
[2021-10-24 17:52:14,538: INFO/MainProcess] Task monolith.background.send_message[248fa7fd-dd43-4a27-93da-2618e8027333] received
[2021-10-24 17:52:14,551: WARNING/ForkPoolWorker-2] <Message 110>
[2021-10-24 17:52:14,551: WARNING/ForkPoolWorker-2] 

[2021-10-24 17:52:14,554: INFO/ForkPoolWorker-2] Task monolith.background.send_message[248fa7fd-dd43-4a27-93da-2618e8027333] succeeded in 0.014826392000003352s: []
[2021-10-24 17:52:15,264: INFO/MainProcess] Task monolith.background.send_message[088d4742-09b7-4d97-9736-4e383f650cc6] received
[2021-10-24 17:52:15,280: WARNING/ForkPoolWorker-2] <Message 111>
[2021-10-24 17:52:15,281: WARNING/ForkPoolWorker-2] 

[2021-10-24 17:52:15,284: INFO/ForkPoolWorker-2] Task monolith.background.send_message[088d4742-09b7-4d97-9736-4e383f650cc6] succeeded in 0.019432485000010047s: []

SIGHUP not supported: Restarting with SIGHUP is unstable on this platform!
[2021-10-24 17:52:21,698: ERROR/MainProcess] Process 'ForkPoolWorker-4' pid:97267 exited with 'exitcode 70'
[2021-10-24 17:52:21,711: ERROR/MainProcess] Process 'ForkPoolWorker-3' pid:97266 exited with 'exitcode 70'
[2021-10-24 17:52:21,722: ERROR/MainProcess] Process 'ForkPoolWorker-2' pid:97265 exited with 'exitcode 70'
[2021-10-24 17:52:21,733: ERROR/MainProcess] Process 'ForkPoolWorker-1' pid:97246 exited with 'exitcode 70'
Usage: celery [OPTIONS] COMMAND [ARGS]...

Error: Invalid value for "-A" / "--app": 
Unable to load celery application.
While trying to load the module monolith.background the following error occurred:
Traceback (most recent call last):
  File "/Users/antoniopace/message-in-a-bottle/monolith/venv/lib/python3.9/site-packages/celery/bin/celery.py", line 53, in convert
    return find_app(value)
  File "/Users/antoniopace/message-in-a-bottle/monolith/venv/lib/python3.9/site-packages/celery/app/utils.py", line 384, in find_app
    sym = symbol_by_name(app, imp=imp)
  File "/Users/antoniopace/message-in-a-bottle/monolith/venv/lib/python3.9/site-packages/kombu/utils/imports.py", line 56, in symbol_by_name
    module = imp(module_name, package=package, **kwargs)
  File "/Users/antoniopace/message-in-a-bottle/monolith/venv/lib/python3.9/site-packages/celery/utils/imports.py", line 100, in import_from_cwd
    return imp(module, package=package)
  File "/Library/Frameworks/Python.framework/Versions/3.9/lib/python3.9/importlib/__init__.py", line 127, in import_module
    return _bootstrap._gcd_import(name[level:], package, level)
  File "<frozen importlib._bootstrap>", line 1030, in _gcd_import
  File "<frozen importlib._bootstrap>", line 1007, in _find_and_load
  File "<frozen importlib._bootstrap>", line 986, in _find_and_load_unlocked
  File "<frozen importlib._bootstrap>", line 680, in _load_unlocked
  File "<frozen importlib._bootstrap_external>", line 790, in exec_module
  File "<frozen importlib._bootstrap>", line 228, in _call_with_frames_removed
  File "/Users/antoniopace/message-in-a-bottle/monolith/__init__.py", line 1, in <module>
    from .app import create_app
  File "/Users/antoniopace/message-in-a-bottle/monolith/app.py", line 7, in <module>
    from monolith.views import blueprints
  File "/Users/antoniopace/message-in-a-bottle/monolith/views/__init__.py", line 4, in <module>
    from .messages import messages
  File "/Users/antoniopace/message-in-a-bottle/monolith/views/messages.py", line 4, in <module>
    from monolith.background import send_message
  File "/Users/antoniopace/message-in-a-bottle/monolith/background.py", line 3
    <<<<<<< HEAD
    ^
SyntaxError: invalid syntax

 
 -------------- celery@MBPro.local v5.1.2 (sun-harmonics)
--- ***** ----- 
-- ******* ---- macOS-10.16-x86_64-i386-64bit 2021-10-25 11:48:46
- *** --- * --- 
- ** ---------- [config]
- ** ---------- .> app:         monolith.background:0x7f974e321a30
- ** ---------- .> transport:   redis://localhost:6379//
- ** ---------- .> results:     redis://localhost:6379/
- *** --- * --- .> concurrency: 4 (prefork)
-- ******* ---- .> task events: OFF (enable -E to monitor tasks in this worker)
--- ***** ----- 
 -------------- [queues]
                .> celery           exchange=celery(direct) key=celery
                

[tasks]
  . monolith.background.send_message

[2021-10-25 11:48:46,406: ERROR/MainProcess] consumer: Cannot connect to redis://localhost:6379//: Error 61 connecting to localhost:6379. Connection refused..
Trying again in 2.00 seconds... (1/100)

[2021-10-25 11:48:48,417: ERROR/MainProcess] consumer: Cannot connect to redis://localhost:6379//: Error 61 connecting to localhost:6379. Connection refused..
Trying again in 4.00 seconds... (2/100)

[2021-10-25 11:48:52,428: ERROR/MainProcess] consumer: Cannot connect to redis://localhost:6379//: Error 61 connecting to localhost:6379. Connection refused..
Trying again in 6.00 seconds... (3/100)

[2021-10-25 11:48:58,443: ERROR/MainProcess] consumer: Cannot connect to redis://localhost:6379//: Error 61 connecting to localhost:6379. Connection refused..
Trying again in 8.00 seconds... (4/100)

[2021-10-25 11:49:06,471: ERROR/MainProcess] consumer: Cannot connect to redis://localhost:6379//: Error 61 connecting to localhost:6379. Connection refused..
Trying again in 10.00 seconds... (5/100)

[2021-10-25 11:49:16,496: ERROR/MainProcess] consumer: Cannot connect to redis://localhost:6379//: Error 61 connecting to localhost:6379. Connection refused..
Trying again in 12.00 seconds... (6/100)

[2021-10-25 11:49:28,541: ERROR/MainProcess] consumer: Cannot connect to redis://localhost:6379//: Error 61 connecting to localhost:6379. Connection refused..
Trying again in 14.00 seconds... (7/100)

 
 -------------- celery@MBPro.local v5.1.2 (sun-harmonics)
--- ***** ----- 
-- ******* ---- macOS-10.16-x86_64-i386-64bit 2021-10-26 15:47:31
- *** --- * --- 
- ** ---------- [config]
- ** ---------- .> app:         monolith.background:0x7fe01dd40910
- ** ---------- .> transport:   redis://localhost:6379//
- ** ---------- .> results:     redis://localhost:6379/
- *** --- * --- .> concurrency: 4 (prefork)
-- ******* ---- .> task events: OFF (enable -E to monitor tasks in this worker)
--- ***** ----- 
 -------------- [queues]
                .> celery           exchange=celery(direct) key=celery
                

[tasks]
  . monolith.background.send_message

[2021-10-26 15:47:31,908: INFO/MainProcess] Connected to redis://localhost:6379//
[2021-10-26 15:47:31,945: INFO/MainProcess] mingle: searching for neighbors
[2021-10-26 15:47:33,161: INFO/MainProcess] mingle: all alone
[2021-10-26 15:47:33,192: INFO/MainProcess] celery@MBPro.local ready.

worker: Hitting Ctrl+C again will terminate all running tasks!

worker: Warm shutdown (MainProcess)
 
 -------------- celery@host-131-114-212-213.m.unipi.it v5.1.2 (sun-harmonics)
--- ***** ----- 
-- ******* ---- macOS-10.16-x86_64-i386-64bit 2021-10-26 17:03:49
- *** --- * --- 
- ** ---------- [config]
- ** ---------- .> app:         monolith.background:0x7f9b81b35910
- ** ---------- .> transport:   redis://localhost:6379//
- ** ---------- .> results:     redis://localhost:6379/
- *** --- * --- .> concurrency: 4 (prefork)
-- ******* ---- .> task events: OFF (enable -E to monitor tasks in this worker)
--- ***** ----- 
 -------------- [queues]
                .> celery           exchange=celery(direct) key=celery
                

[tasks]
  . monolith.background.send_message

[2021-10-26 17:03:49,623: INFO/MainProcess] Connected to redis://localhost:6379//
[2021-10-26 17:03:49,638: INFO/MainProcess] mingle: searching for neighbors
[2021-10-26 17:03:50,680: INFO/MainProcess] mingle: all alone
[2021-10-26 17:03:50,723: INFO/MainProcess] celery@host-131-114-212-213.m.unipi.it ready.

worker: Hitting Ctrl+C again will terminate all running tasks!

worker: Warm shutdown (MainProcess)
